Workbook
Name BIAIDs: '07. BIA'!$B$6:$B$285
Name BusinessUnit: '99. Engine'!$O$4:$O$37
Name BusinessUnits: '10. Risk Assessment'!$C$5
Name BusinessUnits1: ScopeProductsServices[Business Unit]
Name CAPA_BIARefs: '07. BIA'!$B$6:$B$285
Name CAPA_DepRefs: DependencyRegister[Dep ID]
Name CAPA_DocRefs: '18. ISO Docs & Records'!$A$5:$A$24
Name CAPA_DRRefs: ITDRRegister[DR ID]
Name CAPA_RiskRefs: INDEX(RiskAssessment[],0,2)
Name CAPA_RRRefs: RecoveryResponsePlans[R&R ID]
Name DC_1: '09. Risk Assumption Map'!$C$4:$I$4
Name DependencyBIAIDs: '08. Dependency Register'!$C$5:$C$204
Name DivisionSite: '99. Engine'!$P$4:$P$37
Name DivisionSites: ScopeProductsServices[Division / Site]
Name E_1: '06. Application & Equipment'!$I$9
Name E_E: ApplicationEquipmentMaster[Equipment / Building / Utilities]
Name I_A: ApplicationEquipmentMaster[Application]
Name I_S: ApplicationEquipmentMaster[Service]
Name ICT_0: '06. Application & Equipment'!$A$10
Name ICT_1: '06. Application & Equipment'!$G$9
Name ICT_List: '06. Application & Equipment'!$G$9:$H$9
Name lstChainCrit: '99. Engine'!$F$4:$F$7
Name lstCorpCrit: '99. Engine'!$E$4:$E$6
Name lstDepCat: '99. Engine'!$D$4:$D$10
Name lstDRStrategy: '99. Engine'!$J$4:$J$9
Name lstISOStatus: '99. Engine'!$Q$4:$Q$7
Name lstReqCat: '99. Engine'!$M$4:$M$9
Name lstScore: '99. Engine'!$C$4:$C$9
Name lstSPOF: '99. Engine'!$L$4:$L$5
Name lstStatus: '99. Engine'!$G$4:$G$7
Name lstStrategy: '99. Engine'!$H$4:$H$10
Name lstTestResult: '99. Engine'!$I$4:$I$6
Name lstYN: '99. Engine'!$A$4:$A$5
Name lstYPN: '99. Engine'!$B$4:$B$6
Name MTPDMap: '99. Engine'!$S$4:$T$12
Name ProcessProductCodes: ProcessesActivities[Product Code]
Name RequirementStrategyIDs: RequirementsRegister[S&S ID]
Name RiskIDs: INDEX(RiskAssessment[],0,2)
Name S_1: '06. Application & Equipment'!$C$11
Name ScopeNames: ScopeProductsServices[Product / Service]
Name SSIDs: '11. Strategies & Solutions'!$C$5:$C$64
Name StrategyRiskIDs: StrategiesSolutions[Risk ID]

Sheet 00. Document Control
A1: BCM Implementation Toolkit
A2: CONFIDENTIAL | ISO 22301: 7.5 Documented information
A4: Document Control
A5: Version Number | B5: 1
A6: Release Date | B6: 46031
A7: Review Date | B7: =IF(B6="","",EDATE(B6,12)) -> 46396
A8: Status | B8: Draft- under review
A9: Custodian | B9: BCM Function
A11: Prepared by:
A12: Position / Title | B12: Name | C12: Date | D12: Signature
A15: Reviewed by:
A16: Position / Title | B16: Name | C16: Date | D16: Signature
A19: Approved by:
A20: Position / Title | B20: Name | C20: Date | D20: Signature
A23: Version Control History
A24: Version | B24: Effective Date | C24: Change Description | D24: Approved By
A25: =IF($B$5="","",$B$5) -> 1 | B25: =IF($B$6="","",$B$6) -> 46031 | C25: Current controlled version | D25: =IF($B$21="","",$B$21)

Sheet 01. Instructions
A1: How the Toolkit Works - Governance, Colours & Flow (v6)
A2: CONFIDENTIAL: reveals critical organisational infrastructure - distribution restricted to the approved BCM list | ISO 22301: 7.5 Documented information (control & use)
A4: Colour code
A5: WHITE cells | B5: You fill these. Everything the toolkit needs from a human is white.
A6: LIGHT BLUE cells | B6: Automatic - formulas. Do not type here; they read the toolkit and update themselves.
A8: Governance | B8: DATA STEWARD: only the Head of BCM (or a named delegate) issues P&S IDs and unlocks '99. Engine'. REVIEW CYCLE: each BIA block carries Assessment Date / Valid Until - expiry flips the PDCA BIA step to Partial. IDs derive from the static No. column, so sorting or filtering never breaks identity.
A9: Grouping (+/-) | B9: Sheets use Excel grouping: BIA blocks and Risk Assessment associations collapse with the +/- buttons on the left margin; the ISO map groups by clause. Collapse what you are not working on.
A10: Chain & Logic | B10: 1 P&S <-> 1 BIA. Risk = assumption per dependency (1 BIA -> many Risks; 1 Risk -> many BIAs). 1 Risk <-> 1 S&S. 1 S&S -> 1 BCP; 1 BCP -> many S&S. Requirements live one-row-each in 5b. Flow: 0a Profile -> 2 Scope -> 3 BIA -> 3b Dependencies -> 4 RA -> 5 S&S -> 5b Requirements -> 6 RR (BCP) -> 7 Register -> 8 Dashboard -> 11 PDCA -> 14 ISO Map. Docs Register (12) and IT DR (13) plug into the same chain.
A11: Impact Over Time | B11: Nine horizons (6h -> >1 month) with edges on the ERM Operational bands. Score each phase with the ERM rating carried if still down at the END of that phase, using the anchors in '9. Reference Data'. MTPD / RTO / criticality calculate automatically; the value chain overrides upstream with the worst downstream MTPD.
A12: Common Mistakes | B12: x RTO equal to MTPD (toolkit keeps a buffer). x Dependencies typed as long text in one cell - use 3b, one row each. x Requirement flag = Yes in Sheet 5 with no matching row in 5b (the flag turns red). x Deleting rows - clear contents instead. x Scoring without the Sheet 9 anchors.
A13: Growth Headroom | B13: Spare capacity: 45 scope rows, 40 BIA blocks, 28 risks, 60 S&S, 100 BCP rows, 300 requirement rows, 200 dependencies, 30 DR systems. Formulas already cover the spare rows.

Sheet 02. Dashboard
A1: BCM Programme Dashboard - [Company]
A2: Live counters - review weekly - red items need action, not explanation | ISO 22301: 9.1 Monitoring, measurement, analysis, evaluation
A4: Coverage | D4: Risk & Readiness | G4: Governance & Compliance
A5: P&S in scope | B5: =COUNTIF('04. Products & Services'!$I$6:$I$50,"Yes") -> 1 | D5: Risks assessed | E5: =COUNTIF(INDEX(RiskAssessment[],0,2),"RA-*") -> 1 | G5: BCP rows (RR plan) | H5: =COUNTIF('14. Recovery & Response'!$C$6:$C$105,"SS-*") -> 1
A6: BIAs completed | B6: {=SUMPRODUCT(--('07. BIA'!$B$6:$B$285<>""),--ISNUMBER('07. BIA'!$AF$6:$AF$285))} -> 1 | D6: Critical / Significant risks | E6: =COUNTIF('10. Risk Assessment'!$P$5:$P$34,"Critical")+COUNTIF('10. Risk Assessment'!$P$5:$P$34,"Significant") -> 1 | G6: Exercises done / overdue | H6: =COUNT(RecoveryResponsePlans[Actual Exercise Date])&" / "&COUNTIF(RecoveryResponsePlans[Exercise Status],"Overdue") -> 0 / 0
A7: Critical P&S (final) | B7: =COUNTIF('07. BIA'!$W$6:$W$285,"Yes") -> 1 | D7: Priority 1-2 risks (BCP) | E7: =COUNTIF('10. Risk Assessment'!$Q$5:$Q$34,1)+COUNTIF('10. Risk Assessment'!$Q$5:$Q$34,2) -> 1 | G7: DR systems / tested-current | H7: =COUNTIF(ITDRRegister[DR ID],"DR-*")&" / "&COUNTIF(ITDRRegister[Status (auto)],"Tested & Current") -> 0 / 0
A8: P&S-risk associations | B8: {=_xlfn.LET(_xlpm.x,INDEX(RiskAssessment[],0,6),SUMPRODUCT(--(_xlpm.x<>""),LEN(_xlpm.x)-LEN(SUBSTITUTE(_xlpm.x,",",""))+1))} -> 1 | D8: Solutions defined / overdue | E8: =COUNTIF('11. Strategies & Solutions'!$C$5:$C$64,"SS-*")&" / "&COUNTIF('11. Strategies & Solutions'!$T$5:$T$64,"Overdue") -> 1 / 0 | G8: External evidence not evidenced | H8: {=SUMPRODUCT(--(LEFT('18. ISO Docs & Records'!$A$5:$A$24,4)="EXT-"),--(((('18. ISO Docs & Records'!$F$5:$F$24<>"Evidence Filed")*('18. ISO Docs & Records'!$F$5:$F$24<>"Not Applicable"))+('18. ISO Docs & Records'!$S$5:$S$24="Overdue"))>0))} -> 20
A9: Dependencies registered | B9: =COUNTIF('08. Dependency Register'!$B$5:$B$204,"DEP-*") -> 0 | D9: Requirement rows (5b) | E9: =COUNTIF('12. Requirements Register'!$B$5:$B$304,"REQ-*") -> 0 | G9: ISO clauses missing | H9: =COUNTIF('19. ISO 22301 Map'!$D$5:$D$43,"Missing") -> 0
A10: BIA reviews overdue | B10: =SUMPRODUCT(--('07. BIA'!$AG$6:$AG$285<>"")*('07. BIA'!$AG$6:$AG$285<TODAY())) -> 0 | G10: Duplicate S&S mappings | H10: =COUNTIF('11. Strategies & Solutions'!$U$5:$U$64,"DUPLICATE") -> 0
A12: PDCA snapshot
A13: ='17. BCMS Progress (PDCA)'!$C$5 -> Scope & Context (0a Profile + P&S) | B13: ='17. BCMS Progress (PDCA)'!$F$5 -> Partial
A14: ='17. BCMS Progress (PDCA)'!$C$6 -> Leadership & Policy (BCM Policy approved) | B14: ='17. BCMS Progress (PDCA)'!$F$6 -> Not Assessed
A15: ='17. BCMS Progress (PDCA)'!$C$7 -> Corporate BIA (CEO-level criticality) | B15: ='17. BCMS Progress (PDCA)'!$F$7 -> Yes
A16: ='17. BCMS Progress (PDCA)'!$C$8 -> Business Impact Analysis (+ review currency) | B16: ='17. BCMS Progress (PDCA)'!$F$8 -> Yes
A17: ='17. BCMS Progress (PDCA)'!$C$9 -> Dependency Register | B17: ='17. BCMS Progress (PDCA)'!$F$9 -> Yes
A18: ='17. BCMS Progress (PDCA)'!$C$10 -> Risk Assessment (all assumptions rated) | B18: ='17. BCMS Progress (PDCA)'!$F$10 -> Partial
A19: ='17. BCMS Progress (PDCA)'!$C$11 -> Strategies & Solutions (every risk covered) | B19: ='17. BCMS Progress (PDCA)'!$F$11 -> Partial
A20: ='17. BCMS Progress (PDCA)'!$C$12 -> Requirements captured (5b) | B20: ='17. BCMS Progress (PDCA)'!$F$12 -> Partial
A21: ='17. BCMS Progress (PDCA)'!$C$13 -> BCP Development (every S&S in a BCP) | B21: ='17. BCMS Progress (PDCA)'!$F$13 -> Partial
A22: ='17. BCMS Progress (PDCA)'!$C$14 -> IT DR & Cyber Resilience (ISO 22301 8.3 ICT) | B22: ='17. BCMS Progress (PDCA)'!$F$14 -> Not Assessed
A23: ='17. BCMS Progress (PDCA)'!$C$15 -> Exercising & Testing | B23: ='17. BCMS Progress (PDCA)'!$F$15 -> Partial
A24: ='17. BCMS Progress (PDCA)'!$C$16 -> Performance Evaluation (KPIs to Board) | B24: ='17. BCMS Progress (PDCA)'!$F$16 -> Not Assessed
A25: ='17. BCMS Progress (PDCA)'!$C$17 -> Internal Audit of BCMS | B25: ='17. BCMS Progress (PDCA)'!$F$17 -> Not Assessed
A26: ='17. BCMS Progress (PDCA)'!$C$18 -> Management Review | B26: ='17. BCMS Progress (PDCA)'!$F$18 -> Not Assessed
A27: ='17. BCMS Progress (PDCA)'!$C$19 -> Continual Improvement | B27: ='17. BCMS Progress (PDCA)'!$F$19 -> Not Assessed
A29: Corrective Action & Improvement
A30: Open CAPAs | B30: =COUNTIFS(CAPARegister[CAPA ID],"CAPA-*",CAPARegister[Status],"<>Closed",CAPARegister[Status],"<>Cancelled") -> 0 | D30: Overdue CAPAs | E30: =COUNTIF(CAPARegister[Overdue],"Overdue") -> 0 | G30: Effectiveness pending | H30: =COUNTIFS(CAPARegister[Status],"Pending Verification")+COUNTIFS(CAPARegister[Status],"Closed",CAPARegister[Effectiveness],"Pending") -> 0
A31: Critical / High open | B31: =COUNTIFS(CAPARegister[Status],"<>Closed",CAPARegister[Status],"<>Cancelled",CAPARegister[Severity],"Critical")+COUNTIFS(CAPARegister[Status],"<>Closed",CAPARegister[Status],"<>Cancelled",CAPARegister[Severity],"High") -> 0

Sheet 03. Business Unit Profile
A1: Business Unit Profile - BCM Implementation Scope (ISO 22301 Clause 4)
A2: CONFIDENTIAL - Understanding the organization's context, interested parties, and BCMS scope
A4: Section 1 - Organization Identity (ISO 22301 Clause 4.1)
A5: Organization Legal Name
A6: Business Unit Name
A7: Business Unit Code / ID
A8: Parent Division
A9: Headquarters Location
A10: Operating Locations (list)
A11: Date Established
A12: Number of Employees (BU)
A13: Industry Sector
... A16: Section 2 - Leadership & Governance (ISO 22301 Clause 5)
A17: Field | B17: Name | C17: Title | D17: Contact
A27: Section 3 - Internal Context (ISO 22301 Clause 4.1)
A28: Mission Statement
A29: Vision Statement
A30: Strategic Objectives (BU)
A31: Key Products / Services
A32: Annual Revenue (local currency)
A33: Operating Hours
A34: Peak Seasons / Periods
A35: Organizational Structure
A37: Section 4 - External Context (ISO 22301 Clause 4.1)
A38: Primary Regulators
A39: Market Position
... A48: Section 5 - Interested Parties & Requirements (ISO 22301 Clause 4.2)
A49: Interested Party | B49: Requirements / Expectations | C49: How Addressed | D49: Priority
A50: Shareholders / Board
A51: Customers (B2B)
A52: Consumers (End Users)
A53: Employees
A54: Suppliers / Vendors
A55: Regulatory Authorities
A56: Government Agencies
A57: Local Communities
A58: Insurance Providers
A59: Media / Public
A60: Banks / Financial Institutions
A62: Section 6 - BCMS Scope Definition (ISO 22301 Clause 4.3)
...

Sheet 04. Products & Services
A1: Step 1 - Scope: Products & Services + Corporate BIA + Value Chain
A2: Steward issues P&S IDs | ISO 22301: 4.3 Scope; 8.2.2 Prioritised activities
J4: Corporate BIA (CEO-level first check) | N4: Calculated (auto)
A5: No. | B5: P&S ID | C5: Business Unit | D5: Division / Site | E5: Product / Service | F5: Sub-Category | G5: Owner | H5: EVP | I5: In Scope (Y/N) | J5: Corporate BIA Critical | K5: Corporate MBCO (if provided) | L5: Corporate MTPD (if provided) | M5: Corporate MTPD (hours) | N5: BIA Order | O5: BU BIA MTPD
A6: 1 | B6: =IF($E6="","","PS-"&TEXT($A6,"000")) -> PS-001 | C6: ss | D6: hr | E6: cb | I6: Yes | J6: Yes | K6: fill this with the MBCO | M6: {=IF(ISBLANK(L6),"",_xlfn.LET( _xlpm.Num,--_xlfn.TEXTBEFORE(L6," "), _xlpm.Unit,LOWER(_xlfn.TEXTAFTER(L6," ")), _xlfn.SWITCH(_xlpm.Unit, "hour",_xlpm.Num, "hours",_xlpm.Num, "day",_xlpm.Num*24, "days",_xlpm.Num*24, "week",_xlpm.Num*24*7, "weeks",_xlpm.Num*24*7, "month",_xlpm.Num*24*(365.25/12), "months",_xlpm.Num*24*(365.25/12), "") ))} | N6: =IF($I6<>"Yes","",IF($A6="","",COUNTIFS($A$6:$A$50,"<"&$A6,$I$6:$I$50,"Yes")+1)) -> 1 | O6: =IF(ScopeProductsServices[[#This Row],[Product / Service]]="","",IFERROR(_xlfn.LET(_xlpm.r,MATCH(ScopeProductsServices[[#This Row],[Product / Service]],'07. BIA'!$E$6:$E$285,0),_xlpm.b,OFFSET('07. BIA'!$J$6,_xlpm.r-1,0,7,9),IF(COUNT(_xlpm.b)=0,"",IF(MAX(INDEX(_xlpm.b,0,1))>=4,6,IF(MAX(INDEX(_xlpm.b,0,2))>=4,18,IF(MAX(INDEX(_xlpm.b,0,3))>=4,36,IF(MAX(INDEX(_xlpm.b,0,4))>=4,72,IF(MAX(INDEX(_xlpm.b,0,5))>=4,168,IF(MAX(INDEX(_xlpm.b,0,6))>=4,336,IF(MAX(INDEX(_xlpm.b,0,7))>=4,504,IF(MAX(INDEX(_xlpm.b,0,8))>=4,672,"")))))))))),"")) -> 6
A7: 2 | B7: =IF($E7="","","PS-"&TEXT($A7,"000")) | M7: {=IF(ISBLANK(L7),"",_xlfn.LET( _xlpm.Num,--_xlfn.TEXTBEFORE(L7," "), _xlpm.Unit,LOWER(_xlfn.TEXTAFTER(L7," ")), _xlfn.SWITCH(_xlpm.Unit, "hour",_xlpm.Num, "hours",_xlpm.Num, "day",_xlpm.Num*24, "days",_xlpm.Num*24, "week",_xlpm.Num*24*7, "weeks",_xlpm.Num*24*7, "month",_xlpm.Num*24*(365.25/12), "months",_xlpm.Num*24*(365.25/12), "") ))} | N7: =IF($I7<>"Yes","",IF($A7="","",COUNTIFS($A$6:$A$50,"<"&$A7,$I$6:$I$50,"Yes")+1)) | O7: =IF(ScopeProductsServices[[#This Row],[Product / Service]]="","",IFERROR(_xlfn.LET(_xlpm.r,MATCH(ScopeProductsServices[[#This Row],[Product / Service]],'07. BIA'!$E$6:$E$285,0),_xlpm.b,OFFSET('07. BIA'!$J$6,_xlpm.r-1,0,7,9),IF(COUNT(_xlpm.b)=0,"",IF(MAX(INDEX(_xlpm.b,0,1))>=4,6,IF(MAX(INDEX(_xlpm.b,0,2))>=4,18,IF(MAX(INDEX(_xlpm.b,0,3))>=4,36,IF(MAX(INDEX(_xlpm.b,0,4))>=4,72,IF(MAX(INDEX(_xlpm.b,0,5))>=4,168,IF(MAX(INDEX(_xlpm.b,0,6))>=4,336,IF(MAX(INDEX(_xlpm.b,0,7))>=4,504,IF(MAX(INDEX(_xlpm.b,0,8))>=4,672,"")))))))))),""))
A8: 3 | B8: =IF($E8="","","PS-"&TEXT($A8,"000")) | M8: {=IF(ISBLANK(L8),"",_xlfn.LET( _xlpm.Num,--_xlfn.TEXTBEFORE(L8," "), _xlpm.Unit,LOWER(_xlfn.TEXTAFTER(L8," ")), _xlfn.SWITCH(_xlpm.Unit, "hour",_xlpm.Num, "hours",_xlpm.Num, "day",_xlpm.Num*24, "days",_xlpm.Num*24, "week",_xlpm.Num*24*7, "weeks",_xlpm.Num*24*7, "month",_xlpm.Num*24*(365.25/12), "months",_xlpm.Num*24*(365.25/12), "") ))} | N8: =IF($I8<>"Yes","",IF($A8="","",COUNTIFS($A$6:$A$50,"<"&$A8,$I$6:$I$50,"Yes")+1)) | O8: =IF(ScopeProductsServices[[#This Row],[Product / Service]]="","",IFERROR(_xlfn.LET(_xlpm.r,MATCH(ScopeProductsServices[[#This Row],[Product / Service]],'07. BIA'!$E$6:$E$285,0),_xlpm.b,OFFSET('07. BIA'!$J$6,_xlpm.r-1,0,7,9),IF(COUNT(_xlpm.b)=0,"",IF(MAX(INDEX(_xlpm.b,0,1))>=4,6,IF(MAX(INDEX(_xlpm.b,0,2))>=4,18,IF(MAX(INDEX(_xlpm.b,0,3))>=4,36,IF(MAX(INDEX(_xlpm.b,0,4))>=4,72,IF(MAX(INDEX(_xlpm.b,0,5))>=4,168,IF(MAX(INDEX(_xlpm.b,0,6))>=4,336,IF(MAX(INDEX(_xlpm.b,0,7))>=4,504,IF(MAX(INDEX(_xlpm.b,0,8))>=4,672,"")))))))))),""))
A9: 4 | B9: =IF($E9="","","PS-"&TEXT($A9,"000")) | M9: {=IF(ISBLANK(L9),"",_xlfn.LET( _xlpm.Num,--_xlfn.TEXTBEFORE(L9," "), _xlpm.Unit,LOWER(_xlfn.TEXTAFTER(L9," ")), _xlfn.SWITCH(_xlpm.Unit, "hour",_xlpm.Num, "hours",_xlpm.Num, "day",_xlpm.Num*24, "days",_xlpm.Num*24, "week",_xlpm.Num*24*7, "weeks",_xlpm.Num*24*7, "month",_xlpm.Num*24*(365.25/12), "months",_xlpm.Num*24*(365.25/12), "") ))} | N9: =IF($I9<>"Yes","",IF($A9="","",COUNTIFS($A$6:$A$50,"<"&$A9,$I$6:$I$50,"Yes")+1)) | O9: =IF(ScopeProductsServices[[#This Row],[Product / Service]]="","",IFERROR(_xlfn.LET(_xlpm.r,MATCH(ScopeProductsServices[[#This Row],[Product / Service]],'07. BIA'!$E$6:$E$285,0),_xlpm.b,OFFSET('07. BIA'!$J$6,_xlpm.r-1,0,7,9),IF(COUNT(_xlpm.b)=0,"",IF(MAX(INDEX(_xlpm.b,0,1))>=4,6,IF(MAX(INDEX(_xlpm.b,0,2))>=4,18,IF(MAX(INDEX(_xlpm.b,0,3))>=4,36,IF(MAX(INDEX(_xlpm.b,0,4))>=4,72,IF(MAX(INDEX(_xlpm.b,0,5))>=4,168,IF(MAX(INDEX(_xlpm.b,0,6))>=4,336,IF(MAX(INDEX(_xlpm.b,0,7))>=4,504,IF(MAX(INDEX(_xlpm.b,0,8))>=4,672,"")))))))))),""))
A10: 5 | B10: =IF($E10="","","PS-"&TEXT($A10,"000")) | M10: {=IF(ISBLANK(L10),"",_xlfn.LET( _xlpm.Num,--_xlfn.TEXTBEFORE(L10," "), _xlpm.Unit,LOWER(_xlfn.TEXTAFTER(L10," ")), _xlfn.SWITCH(_xlpm.Unit, "hour",_xlpm.Num, "hours",_xlpm.Num, "day",_xlpm.Num*24, "days",_xlpm.Num*24, "week",_xlpm.Num*24*7, "weeks",_xlpm.Num*24*7, "month",_xlpm.Num*24*(365.25/12), "months",_xlpm.Num*24*(365.25/12), "") ))} | N10: =IF($I10<>"Yes","",IF($A10="","",COUNTIFS($A$6:$A$50,"<"&$A10,$I$6:$I$50,"Yes")+1)) | O10: =IF(ScopeProductsServices[[#This Row],[Product / Service]]="","",IFERROR(_xlfn.LET(_xlpm.r,MATCH(ScopeProductsServices[[#This Row],[Product / Service]],'07. BIA'!$E$6:$E$285,0),_xlpm.b,OFFSET('07. BIA'!$J$6,_xlpm.r-1,0,7,9),IF(COUNT(_xlpm.b)=0,"",IF(MAX(INDEX(_xlpm.b,0,1))>=4,6,IF(MAX(INDEX(_xlpm.b,0,2))>=4,18,IF(MAX(INDEX(_xlpm.b,0,3))>=4,36,IF(MAX(INDEX(_xlpm.b,0,4))>=4,72,IF(MAX(INDEX(_xlpm.b,0,5))>=4,168,IF(MAX(INDEX(_xlpm.b,0,6))>=4,336,IF(MAX(INDEX(_xlpm.b,0,7))>=4,504,IF(MAX(INDEX(_xlpm.b,0,8))>=4,672,"")))))))))),""))
A11: 6 | B11: =IF($E11="","","PS-"&TEXT($A11,"000")) | M11: {=IF(ISBLANK(L11),"",_xlfn.LET( _xlpm.Num,--_xlfn.TEXTBEFORE(L11," "), _xlpm.Unit,LOWER(_xlfn.TEXTAFTER(L11," ")), _xlfn.SWITCH(_xlpm.Unit, "hour",_xlpm.Num, "hours",_xlpm.Num, "day",_xlpm.Num*24, "days",_xlpm.Num*24, "week",_xlpm.Num*24*7, "weeks",_xlpm.Num*24*7, "month",_xlpm.Num*24*(365.25/12), "months",_xlpm.Num*24*(365.25/12), "") ))} | N11: =IF($I11<>"Yes","",IF($A11="","",COUNTIFS($A$6:$A$50,"<"&$A11,$I$6:$I$50,"Yes")+1)) | O11: =IF(ScopeProductsServices[[#This Row],[Product / Service]]="","",IFERROR(_xlfn.LET(_xlpm.r,MATCH(ScopeProductsServices[[#This Row],[Product / Service]],'07. BIA'!$E$6:$E$285,0),_xlpm.b,OFFSET('07. BIA'!$J$6,_xlpm.r-1,0,7,9),IF(COUNT(_xlpm.b)=0,"",IF(MAX(INDEX(_xlpm.b,0,1))>=4,6,IF(MAX(INDEX(_xlpm.b,0,2))>=4,18,IF(MAX(INDEX(_xlpm.b,0,3))>=4,36,IF(MAX(INDEX(_xlpm.b,0,4))>=4,72,IF(MAX(INDEX(_xlpm.b,0,5))>=4,168,IF(MAX(INDEX(_xlpm.b,0,6))>=4,336,IF(MAX(INDEX(_xlpm.b,0,7))>=4,504,IF(MAX(INDEX(_xlpm.b,0,8))>=4,672,"")))))))))),""))
A12: 7 | B12: =IF($E12="","","PS-"&TEXT($A12,"000")) | M12: {=IF(ISBLANK(L12),"",_xlfn.LET( _xlpm.Num,--_xlfn.TEXTBEFORE(L12," "), _xlpm.Unit,LOWER(_xlfn.TEXTAFTER(L12," ")), _xlfn.SWITCH(_xlpm.Unit, "hour",_xlpm.Num, "hours",_xlpm.Num, "day",_xlpm.Num*24, "days",_xlpm.Num*24, "week",_xlpm.Num*24*7, "weeks",_xlpm.Num*24*7, "month",_xlpm.Num*24*(365.25/12), "months",_xlpm.Num*24*(365.25/12), "") ))} | N12: =IF($I12<>"Yes","",IF($A12="","",COUNTIFS($A$6:$A$50,"<"&$A12,$I$6:$I$50,"Yes")+1)) | O12: =IF(ScopeProductsServices[[#This Row],[Product / Service]]="","",IFERROR(_xlfn.LET(_xlpm.r,MATCH(ScopeProductsServices[[#This Row],[Product / Service]],'07. BIA'!$E$6:$E$285,0),_xlpm.b,OFFSET('07. BIA'!$J$6,_xlpm.r-1,0,7,9),IF(COUNT(_xlpm.b)=0,"",IF(MAX(INDEX(_xlpm.b,0,1))>=4,6,IF(MAX(INDEX(_xlpm.b,0,2))>=4,18,IF(MAX(INDEX(_xlpm.b,0,3))>=4,36,IF(MAX(INDEX(_xlpm.b,0,4))>=4,72,IF(MAX(INDEX(_xlpm.b,0,5))>=4,168,IF(MAX(INDEX(_xlpm.b,0,6))>=4,336,IF(MAX(INDEX(_xlpm.b,0,7))>=4,504,IF(MAX(INDEX(_xlpm.b,0,8))>=4,672,"")))))))))),""))
A13: 8 | B13: =IF($E13="","","PS-"&TEXT($A13,"000")) | M13: {=IF(ISBLANK(L13),"",_xlfn.LET( _xlpm.Num,--_xlfn.TEXTBEFORE(L13," "), _xlpm.Unit,LOWER(_xlfn.TEXTAFTER(L13," ")), _xlfn.SWITCH(_xlpm.Unit, "hour",_xlpm.Num, "hours",_xlpm.Num, "day",_xlpm.Num*24, "days",_xlpm.Num*24, "week",_xlpm.Num*24*7, "weeks",_xlpm.Num*24*7, "month",_xlpm.Num*24*(365.25/12), "months",_xlpm.Num*24*(365.25/12), "") ))} | N13: =IF($I13<>"Yes","",IF($A13="","",COUNTIFS($A$6:$A$50,"<"&$A13,$I$6:$I$50,"Yes")+1)) | O13: =IF(ScopeProductsServices[[#This Row],[Product / Service]]="","",IFERROR(_xlfn.LET(_xlpm.r,MATCH(ScopeProductsServices[[#This Row],[Product / Service]],'07. BIA'!$E$6:$E$285,0),_xlpm.b,OFFSET('07. BIA'!$J$6,_xlpm.r-1,0,7,9),IF(COUNT(_xlpm.b)=0,"",IF(MAX(INDEX(_xlpm.b,0,1))>=4,6,IF(MAX(INDEX(_xlpm.b,0,2))>=4,18,IF(MAX(INDEX(_xlpm.b,0,3))>=4,36,IF(MAX(INDEX(_xlpm.b,0,4))>=4,72,IF(MAX(INDEX(_xlpm.b,0,5))>=4,168,IF(MAX(INDEX(_xlpm.b,0,6))>=4,336,IF(MAX(INDEX(_xlpm.b,0,7))>=4,504,IF(MAX(INDEX(_xlpm.b,0,8))>=4,672,"")))))))))),""))
A14: 9 | B14: =IF($E14="","","PS-"&TEXT($A14,"000")) | M14: {=IF(ISBLANK(L14),"",_xlfn.LET( _xlpm.Num,--_xlfn.TEXTBEFORE(L14," "), _xlpm.Unit,LOWER(_xlfn.TEXTAFTER(L14," ")), _xlfn.SWITCH(_xlpm.Unit, "hour",_xlpm.Num, "hours",_xlpm.Num, "day",_xlpm.Num*24, "days",_xlpm.Num*24, "week",_xlpm.Num*24*7, "weeks",_xlpm.Num*24*7, "month",_xlpm.Num*24*(365.25/12), "months",_xlpm.Num*24*(365.25/12), "") ))} | N14: =IF($I14<>"Yes","",IF($A14="","",COUNTIFS($A$6:$A$50,"<"&$A14,$I$6:$I$50,"Yes")+1)) | O14: =IF(ScopeProductsServices[[#This Row],[Product / Service]]="","",IFERROR(_xlfn.LET(_xlpm.r,MATCH(ScopeProductsServices[[#This Row],[Product / Service]],'07. BIA'!$E$6:$E$285,0),_xlpm.b,OFFSET('07. BIA'!$J$6,_xlpm.r-1,0,7,9),IF(COUNT(_xlpm.b)=0,"",IF(MAX(INDEX(_xlpm.b,0,1))>=4,6,IF(MAX(INDEX(_xlpm.b,0,2))>=4,18,IF(MAX(INDEX(_xlpm.b,0,3))>=4,36,IF(MAX(INDEX(_xlpm.b,0,4))>=4,72,IF(MAX(INDEX(_xlpm.b,0,5))>=4,168,IF(MAX(INDEX(_xlpm.b,0,6))>=4,336,IF(MAX(INDEX(_xlpm.b,0,7))>=4,504,IF(MAX(INDEX(_xlpm.b,0,8))>=4,672,"")))))))))),""))
A15: 10 | B15: =IF($E15="","","PS-"&TEXT($A15,"000")) | M15: {=IF(ISBLANK(L15),"",_xlfn.LET( _xlpm.Num,--_xlfn.TEXTBEFORE(L15," "), _xlpm.Unit,LOWER(_xlfn.TEXTAFTER(L15," ")), _xlfn.SWITCH(_xlpm.Unit, "hour",_xlpm.Num, "hours",_xlpm.Num, "day",_xlpm.Num*24, "days",_xlpm.Num*24, "week",_xlpm.Num*24*7, "weeks",_xlpm.Num*24*7, "month",_xlpm.Num*24*(365.25/12), "months",_xlpm.Num*24*(365.25/12), "") ))} | N15: =IF($I15<>"Yes","",IF($A15="","",COUNTIFS($A$6:$A$50,"<"&$A15,$I$6:$I$50,"Yes")+1)) | O15: =IF(ScopeProductsServices[[#This Row],[Product / Service]]="","",IFERROR(_xlfn.LET(_xlpm.r,MATCH(ScopeProductsServices[[#This Row],[Product / Service]],'07. BIA'!$E$6:$E$285,0),_xlpm.b,OFFSET('07. BIA'!$J$6,_xlpm.r-1,0,7,9),IF(COUNT(_xlpm.b)=0,"",IF(MAX(INDEX(_xlpm.b,0,1))>=4,6,IF(MAX(INDEX(_xlpm.b,0,2))>=4,18,IF(MAX(INDEX(_xlpm.b,0,3))>=4,36,IF(MAX(INDEX(_xlpm.b,0,4))>=4,72,IF(MAX(INDEX(_xlpm.b,0,5))>=4,168,IF(MAX(INDEX(_xlpm.b,0,6))>=4,336,IF(MAX(INDEX(_xlpm.b,0,7))>=4,504,IF(MAX(INDEX(_xlpm.b,0,8))>=4,672,"")))))))))),""))
A16: 11 | B16: =IF($E16="","","PS-"&TEXT($A16,"000")) | M16: {=IF(ISBLANK(L16),"",_xlfn.LET( _xlpm.Num,--_xlfn.TEXTBEFORE(L16," "), _xlpm.Unit,LOWER(_xlfn.TEXTAFTER(L16," ")), _xlfn.SWITCH(_xlpm.Unit, "hour",_xlpm.Num, "hours",_xlpm.Num, "day",_xlpm.Num*24, "days",_xlpm.Num*24, "week",_xlpm.Num*24*7, "weeks",_xlpm.Num*24*7, "month",_xlpm.Num*24*(365.25/12), "months",_xlpm.Num*24*(365.25/12), "") ))} | N16: =IF($I16<>"Yes","",IF($A16="","",COUNTIFS($A$6:$A$50,"<"&$A16,$I$6:$I$50,"Yes")+1)) | O16: =IF(ScopeProductsServices[[#This Row],[Product / Service]]="","",IFERROR(_xlfn.LET(_xlpm.r,MATCH(ScopeProductsServices[[#This Row],[Product / Service]],'07. BIA'!$E$6:$E$285,0),_xlpm.b,OFFSET('07. BIA'!$J$6,_xlpm.r-1,0,7,9),IF(COUNT(_xlpm.b)=0,"",IF(MAX(INDEX(_xlpm.b,0,1))>=4,6,IF(MAX(INDEX(_xlpm.b,0,2))>=4,18,IF(MAX(INDEX(_xlpm.b,0,3))>=4,36,IF(MAX(INDEX(_xlpm.b,0,4))>=4,72,IF(MAX(INDEX(_xlpm.b,0,5))>=4,168,IF(MAX(INDEX(_xlpm.b,0,6))>=4,336,IF(MAX(INDEX(_xlpm.b,0,7))>=4,504,IF(MAX(INDEX(_xlpm.b,0,8))>=4,672,"")))))))))),""))
A17: 12 | B17: =IF($E17="","","PS-"&TEXT($A17,"000")) | M17: {=IF(ISBLANK(L17),"",_xlfn.LET( _xlpm.Num,--_xlfn.TEXTBEFORE(L17," "), _xlpm.Unit,LOWER(_xlfn.TEXTAFTER(L17," ")), _xlfn.SWITCH(_xlpm.Unit, "hour",_xlpm.Num, "hours",_xlpm.Num, "day",_xlpm.Num*24, "days",_xlpm.Num*24, "week",_xlpm.Num*24*7, "weeks",_xlpm.Num*24*7, "month",_xlpm.Num*24*(365.25/12), "months",_xlpm.Num*24*(365.25/12), "") ))} | N17: =IF($I17<>"Yes","",IF($A17="","",COUNTIFS($A$6:$A$50,"<"&$A17,$I$6:$I$50,"Yes")+1)) | O17: =IF(ScopeProductsServices[[#This Row],[Product / Service]]="","",IFERROR(_xlfn.LET(_xlpm.r,MATCH(ScopeProductsServices[[#This Row],[Product / Service]],'07. BIA'!$E$6:$E$285,0),_xlpm.b,OFFSET('07. BIA'!$J$6,_xlpm.r-1,0,7,9),IF(COUNT(_xlpm.b)=0,"",IF(MAX(INDEX(_xlpm.b,0,1))>=4,6,IF(MAX(INDEX(_xlpm.b,0,2))>=4,18,IF(MAX(INDEX(_xlpm.b,0,3))>=4,36,IF(MAX(INDEX(_xlpm.b,0,4))>=4,72,IF(MAX(INDEX(_xlpm.b,0,5))>=4,168,IF(MAX(INDEX(_xlpm.b,0,6))>=4,336,IF(MAX(INDEX(_xlpm.b,0,7))>=4,504,IF(MAX(INDEX(_xlpm.b,0,8))>=4,672,"")))))))))),""))
A18: 13 | B18: =IF($E18="","","PS-"&TEXT($A18,"000")) | M18: {=IF(ISBLANK(L18),"",_xlfn.LET( _xlpm.Num,--_xlfn.TEXTBEFORE(L18," "), _xlpm.Unit,LOWER(_xlfn.TEXTAFTER(L18," ")), _xlfn.SWITCH(_xlpm.Unit, "hour",_xlpm.Num, "hours",_xlpm.Num, "day",_xlpm.Num*24, "days",_xlpm.Num*24, "week",_xlpm.Num*24*7, "weeks",_xlpm.Num*24*7, "month",_xlpm.Num*24*(365.25/12), "months",_xlpm.Num*24*(365.25/12), "") ))} | N18: =IF($I18<>"Yes","",IF($A18="","",COUNTIFS($A$6:$A$50,"<"&$A18,$I$6:$I$50,"Yes")+1)) | O18: =IF(ScopeProductsServices[[#This Row],[Product / Service]]="","",IFERROR(_xlfn.LET(_xlpm.r,MATCH(ScopeProductsServices[[#This Row],[Product / Service]],'07. BIA'!$E$6:$E$285,0),_xlpm.b,OFFSET('07. BIA'!$J$6,_xlpm.r-1,0,7,9),IF(COUNT(_xlpm.b)=0,"",IF(MAX(INDEX(_xlpm.b,0,1))>=4,6,IF(MAX(INDEX(_xlpm.b,0,2))>=4,18,IF(MAX(INDEX(_xlpm.b,0,3))>=4,36,IF(MAX(INDEX(_xlpm.b,0,4))>=4,72,IF(MAX(INDEX(_xlpm.b,0,5))>=4,168,IF(MAX(INDEX(_xlpm.b,0,6))>=4,336,IF(MAX(INDEX(_xlpm.b,0,7))>=4,504,IF(MAX(INDEX(_xlpm.b,0,8))>=4,672,"")))))))))),""))
... A50: 45 | B50: =IF($E50="","","PS-"&TEXT($A50,"000")) | M50: {=IF(ISBLANK(L50),"",_xlfn.LET( _xlpm.Num,--_xlfn.TEXTBEFORE(L50," "), _xlpm.Unit,LOWER(_xlfn.TEXTAFTER(L50," ")), _xlfn.SWITCH(_xlpm.Unit, "hour",_xlpm.Num, "hours",_xlpm.Num, "day",_xlpm.Num*24, "days",_xlpm.Num*24, "week",_xlpm.Num*24*7, "weeks",_xlpm.Num*24*7, "month",_xlpm.Num*24*(365.25/12), "months",_xlpm.Num*24*(365.25/12), "") ))} | N50: =IF($I50<>"Yes","",IF($A50="","",COUNTIFS($A$6:$A$50,"<"&$A50,$I$6:$I$50,"Yes")+1)) | O50: =IF(ScopeProductsServices[[#This Row],[Product / Service]]="","",IFERROR(_xlfn.LET(_xlpm.r,MATCH(ScopeProductsServices[[#This Row],[Product / Service]],'07. BIA'!$E$6:$E$285,0),_xlpm.b,OFFSET('07. BIA'!$J$6,_xlpm.r-1,0,7,9),IF(COUNT(_xlpm.b)=0,"",IF(MAX(INDEX(_xlpm.b,0,1))>=4,6,IF(MAX(INDEX(_xlpm.b,0,2))>=4,18,IF(MAX(INDEX(_xlpm.b,0,3))>=4,36,IF(MAX(INDEX(_xlpm.b,0,4))>=4,72,IF(MAX(INDEX(_xlpm.b,0,5))>=4,168,IF(MAX(INDEX(_xlpm.b,0,6))>=4,336,IF(MAX(INDEX(_xlpm.b,0,7))>=4,504,IF(MAX(INDEX(_xlpm.b,0,8))>=4,672,"")))))))))),""))

Sheet 05. Processes & Activities
A1: Step 1 - Scope: Products & Services + Corporate BIA + Value Chain
A2: Steward issues P&S IDs | ISO 22301: 4.3 Scope; 8.2.2 Prioritised activities
A4: Sl # | B4: Product Code | C4: Product & Services | D4: Activities performed within the process | E4: Frequency of Activity | F4: Peak Period | G4: Rationale for Peak Period | H4: Current Staff to Perform Activity | I4: Activity Can be Performed Remotely? | J4: BlA level MTPD in hours | K4: BIA Level RTO in hours | L4: Remark
A5: 1 | B5: PS-001 | C5: =IFERROR(VLOOKUP(B5,'04. Products & Services'!$B$6:$E$50,4,FALSE),"") -> cb | J5: =IF($B5="","",_xlfn.LET(_xlpm.x,_xlfn.XLOOKUP($B5,'07. BIA'!$F$6:$F$285,'07. BIA'!$AA$6:$AA$285,""),IF(_xlpm.x=0,"",_xlpm.x))) -> 6 | K5: =IF($B5="","",_xlfn.LET(_xlpm.x,_xlfn.XLOOKUP($B5,'07. BIA'!$F$6:$F$285,'07. BIA'!$AD$6:$AD$285,""),IF(_xlpm.x=0,"",_xlpm.x))) -> 168
A6: 2 | C6: =IFERROR(VLOOKUP(B6,'04. Products & Services'!$B$6:$E$50,4,FALSE),"") | J6: =IF($B6="","",_xlfn.LET(_xlpm.x,_xlfn.XLOOKUP($B6,'07. BIA'!$F$6:$F$285,'07. BIA'!$AA$6:$AA$285,""),IF(_xlpm.x=0,"",_xlpm.x))) | K6: =IF($B6="","",_xlfn.LET(_xlpm.x,_xlfn.XLOOKUP($B6,'07. BIA'!$F$6:$F$285,'07. BIA'!$AD$6:$AD$285,""),IF(_xlpm.x=0,"",_xlpm.x)))
A7: 3 | C7: =IFERROR(VLOOKUP(B7,'04. Products & Services'!$B$6:$E$50,4,FALSE),"") | J7: =IF($B7="","",_xlfn.LET(_xlpm.x,_xlfn.XLOOKUP($B7,'07. BIA'!$F$6:$F$285,'07. BIA'!$AA$6:$AA$285,""),IF(_xlpm.x=0,"",_xlpm.x))) | K7: =IF($B7="","",_xlfn.LET(_xlpm.x,_xlfn.XLOOKUP($B7,'07. BIA'!$F$6:$F$285,'07. BIA'!$AD$6:$AD$285,""),IF(_xlpm.x=0,"",_xlpm.x)))
A8: 4 | C8: =IFERROR(VLOOKUP(B8,'04. Products & Services'!$B$6:$E$50,4,FALSE),"") | J8: =IF($B8="","",_xlfn.LET(_xlpm.x,_xlfn.XLOOKUP($B8,'07. BIA'!$F$6:$F$285,'07. BIA'!$AA$6:$AA$285,""),IF(_xlpm.x=0,"",_xlpm.x))) | K8: =IF($B8="","",_xlfn.LET(_xlpm.x,_xlfn.XLOOKUP($B8,'07. BIA'!$F$6:$F$285,'07. BIA'!$AD$6:$AD$285,""),IF(_xlpm.x=0,"",_xlpm.x)))
A9: 5 | C9: =IFERROR(VLOOKUP(B9,'04. Products & Services'!$B$6:$E$50,4,FALSE),"") | J9: =IF($B9="","",_xlfn.LET(_xlpm.x,_xlfn.XLOOKUP($B9,'07. BIA'!$F$6:$F$285,'07. BIA'!$AA$6:$AA$285,""),IF(_xlpm.x=0,"",_xlpm.x))) | K9: =IF($B9="","",_xlfn.LET(_xlpm.x,_xlfn.XLOOKUP($B9,'07. BIA'!$F$6:$F$285,'07. BIA'!$AD$6:$AD$285,""),IF(_xlpm.x=0,"",_xlpm.x)))
A10: 6 | C10: =IFERROR(VLOOKUP(B10,'04. Products & Services'!$B$6:$E$50,4,FALSE),"") | J10: =IF($B10="","",_xlfn.LET(_xlpm.x,_xlfn.XLOOKUP($B10,'07. BIA'!$F$6:$F$285,'07. BIA'!$AA$6:$AA$285,""),IF(_xlpm.x=0,"",_xlpm.x))) | K10: =IF($B10="","",_xlfn.LET(_xlpm.x,_xlfn.XLOOKUP($B10,'07. BIA'!$F$6:$F$285,'07. BIA'!$AD$6:$AD$285,""),IF(_xlpm.x=0,"",_xlpm.x)))
A11: 7 | C11: =IFERROR(VLOOKUP(B11,'04. Products & Services'!$B$6:$E$50,4,FALSE),"") | J11: =IF($B11="","",_xlfn.LET(_xlpm.x,_xlfn.XLOOKUP($B11,'07. BIA'!$F$6:$F$285,'07. BIA'!$AA$6:$AA$285,""),IF(_xlpm.x=0,"",_xlpm.x))) | K11: =IF($B11="","",_xlfn.LET(_xlpm.x,_xlfn.XLOOKUP($B11,'07. BIA'!$F$6:$F$285,'07. BIA'!$AD$6:$AD$285,""),IF(_xlpm.x=0,"",_xlpm.x)))
A12: 8 | C12: =IFERROR(VLOOKUP(B12,'04. Products & Services'!$B$6:$E$50,4,FALSE),"") | J12: =IF($B12="","",_xlfn.LET(_xlpm.x,_xlfn.XLOOKUP($B12,'07. BIA'!$F$6:$F$285,'07. BIA'!$AA$6:$AA$285,""),IF(_xlpm.x=0,"",_xlpm.x))) | K12: =IF($B12="","",_xlfn.LET(_xlpm.x,_xlfn.XLOOKUP($B12,'07. BIA'!$F$6:$F$285,'07. BIA'!$AD$6:$AD$285,""),IF(_xlpm.x=0,"",_xlpm.x)))
A13: 9 | C13: =IFERROR(VLOOKUP(B13,'04. Products & Services'!$B$6:$E$50,4,FALSE),"") | J13: =IF($B13="","",_xlfn.LET(_xlpm.x,_xlfn.XLOOKUP($B13,'07. BIA'!$F$6:$F$285,'07. BIA'!$AA$6:$AA$285,""),IF(_xlpm.x=0,"",_xlpm.x))) | K13: =IF($B13="","",_xlfn.LET(_xlpm.x,_xlfn.XLOOKUP($B13,'07. BIA'!$F$6:$F$285,'07. BIA'!$AD$6:$AD$285,""),IF(_xlpm.x=0,"",_xlpm.x)))
A14: 10 | C14: =IFERROR(VLOOKUP(B14,'04. Products & Services'!$B$6:$E$50,4,FALSE),"") | J14: =IF($B14="","",_xlfn.LET(_xlpm.x,_xlfn.XLOOKUP($B14,'07. BIA'!$F$6:$F$285,'07. BIA'!$AA$6:$AA$285,""),IF(_xlpm.x=0,"",_xlpm.x))) | K14: =IF($B14="","",_xlfn.LET(_xlpm.x,_xlfn.XLOOKUP($B14,'07. BIA'!$F$6:$F$285,'07. BIA'!$AD$6:$AD$285,""),IF(_xlpm.x=0,"",_xlpm.x)))
A15: 11 | C15: =IFERROR(VLOOKUP(B15,'04. Products & Services'!$B$6:$E$50,4,FALSE),"") | J15: =IF($B15="","",_xlfn.LET(_xlpm.x,_xlfn.XLOOKUP($B15,'07. BIA'!$F$6:$F$285,'07. BIA'!$AA$6:$AA$285,""),IF(_xlpm.x=0,"",_xlpm.x))) | K15: =IF($B15="","",_xlfn.LET(_xlpm.x,_xlfn.XLOOKUP($B15,'07. BIA'!$F$6:$F$285,'07. BIA'!$AD$6:$AD$285,""),IF(_xlpm.x=0,"",_xlpm.x)))
A16: 12 | C16: =IFERROR(VLOOKUP(B16,'04. Products & Services'!$B$6:$E$50,4,FALSE),"") | J16: =IF($B16="","",_xlfn.LET(_xlpm.x,_xlfn.XLOOKUP($B16,'07. BIA'!$F$6:$F$285,'07. BIA'!$AA$6:$AA$285,""),IF(_xlpm.x=0,"",_xlpm.x))) | K16: =IF($B16="","",_xlfn.LET(_xlpm.x,_xlfn.XLOOKUP($B16,'07. BIA'!$F$6:$F$285,'07. BIA'!$AD$6:$AD$285,""),IF(_xlpm.x=0,"",_xlpm.x)))
A17: 13 | C17: =IFERROR(VLOOKUP(B17,'04. Products & Services'!$B$6:$E$50,4,FALSE),"") | J17: =IF($B17="","",_xlfn.LET(_xlpm.x,_xlfn.XLOOKUP($B17,'07. BIA'!$F$6:$F$285,'07. BIA'!$AA$6:$AA$285,""),IF(_xlpm.x=0,"",_xlpm.x))) | K17: =IF($B17="","",_xlfn.LET(_xlpm.x,_xlfn.XLOOKUP($B17,'07. BIA'!$F$6:$F$285,'07. BIA'!$AD$6:$AD$285,""),IF(_xlpm.x=0,"",_xlpm.x)))
... A211: 207 | C211: =IFERROR(VLOOKUP(B211,'04. Products & Services'!$B$6:$E$50,4,FALSE),"") | J211: =IF($B211="","",_xlfn.LET(_xlpm.x,_xlfn.XLOOKUP($B211,'07. BIA'!$F$6:$F$285,'07. BIA'!$AA$6:$AA$285,""),IF(_xlpm.x=0,"",_xlpm.x))) | K211: =IF($B211="","",_xlfn.LET(_xlpm.x,_xlfn.XLOOKUP($B211,'07. BIA'!$F$6:$F$285,'07. BIA'!$AD$6:$AD$285,""),IF(_xlpm.x=0,"",_xlpm.x)))

Sheet 06. Application & Equipment
A1: Step 3c. Application equip list
A2: one row per dependency | ISO 22301: 8.2.2 Dependencies & supporting resources
A5: Note: | B5: Here list of applications and services related to IT and equipment and applications related to OT to be captured by BU team.
F8: Sl # | G8: ICT | I8: Equipment / Building / Utilities
A9: IT dependencies | C9: Sub dependencies | F9: Column1 | G9: Application | H9: Service | I9: Equipment / Building / Utilities
A10: ICT | C10: Application | F10: 1
A11: Equipment / Building / Utilities | C11: Service | F11: 2
C12: Equipment / Building / Utilities | F12: 3
F13: 4
F14: 5
F15: 6
F16: 7
F17: 8
F18: 9
F19: 10
F20: 11
F21: 12
F22: 13
F23: 14
F24: 15
... F34: 25

Sheet 07. BIA
A1: Step 2 - Business Impact Analysis (Product & Service Level)
A2: ISO 22301: 8.2.2 Business impact analysis
A4: No. | B4: BIA # | C4: Business Unit | D4: Division / Site | E4: Product / Service (auto - value-chain order) | F4: Product / Service ID | G4: Risk Identification | I4: Impact Type | J4: Process Unavailability Impact Over Time (1-5) - anchors in Sheet 9 | S4: Criticality (Corporate cascade) | X4: MBCO & Recovery Targets | AH4: Linked Records (auto)
G5: Dependencies | H5: Will it interrupt the operation? (Y/N) | J5: Up to 6 Hours | K5: Up to 18 Hours | L5: Up to 36 Hours | M5: Up to 3 Days | N5: Up to 1 Week | O5: Up to 2 Weeks | P5: Up to 3 Weeks | Q5: Up to 1 month | R5: More than 1 Month | S5: Max Impact (auto) | T5: Max Impact Type (auto) | U5: Corporate Critical (auto) | V5: BU Critical (Y/N) | W5: Critical - Final (auto) | X5: MBCO - Corporate (auto) | Y5: MBCO - BU | Z5: Rationale / Supporting Reasons | AA5: MTPD (auto) hours | AB5: CEO MTPD | AC5: RTO | AD5: RTO (auto) in hours | AE5: RPO (fill if Data/ICT = Yes) in hours | AF5: Assessment Date | AG5: Valid Until (auto +12 mo) | AH5: Risk IDs | AI5: S&S # | AJ5: R&R IDs
A6: 1 | B6: =IF($E6="","","BIA-"&TEXT(1,"000")) -> BIA-001 | C6: =IFERROR(INDEX(BusinessUnits1,MATCH(A6,'04. Products & Services'!$N$6:$N$50,0)),"") -> ss | D6: =IFERROR(INDEX(DivisionSites,MATCH(A6,'04. Products & Services'!$N$6:$N$50,0)),"") -> hr | E6: =IFERROR(INDEX(ScopeNames,MATCH(A6,'04. Products & Services'!$N$6:$N$50,0)),"") -> cb | F6: =_xlfn.XLOOKUP(E6,'04. Products & Services'!$E$5:$E$50,'04. Products & Services'!$B$5:$B$50,"") -> PS-001 | G6: People | H6: Yes | I6: Financial | J6: 1 | K6: 2 | L6: 3 | M6: 3 | N6: 4 | O6: 4 | S6: =IF(COUNT(J6:R12)=0,"",MAX(J6:R12)) -> 5 | T6: =IF($S$6="","",IF(COUNT(J6:R6)=0,"",IF(MAX(J6:R6)>3,$I6,""))) -> Financial | U6: {=IF($E6="","",_xlfn.LET(_xlpm.matches,_xlfn._xlws.FILTER('04. Products & Services'!$J$6:$J$50,'04. Products & Services'!$E$6:$E$50=$E6,""),_xlpm.n,COUNTIF($E$6:$E6,$E6),_xlpm.v,IFERROR(INDEX(_xlpm.matches,_xlpm.n),""),IF(OR(_xlpm.v="",_xlpm.v=0),"",_xlpm.v)))} -> Yes | V6: Yes | W6: =IF($E6="","",IF(OR($U6="Yes",$V6="Yes"),"Yes",IF(AND($U6="No",$V6="No"),"No",IF(AND($U6="Under Evaluation",$V6="No"),"Under Evaluation","")))) -> Yes | X6: =IF($E6="","",IFERROR(_xlfn.LET(_xlpm.v,INDEX('04. Products & Services'!$K$6:$K$50,MATCH($E6,ScopeNames,0)),IF(_xlpm.v="","",_xlpm.v)),"")) -> fill this with the MBCO | AA6: =IF($E6="","",IF(COUNT(J6:R12)=0,"",IF(MAX(J6:J12)>=4,6,IF(MAX(K6:K12)>=4,18,IF(MAX(L6:L12)>=4,36,IF(MAX(M6:M12)>=4,72,IF(MAX(N6:N12)>=4,168,IF(MAX(O6:O12)>=4,336,IF(MAX(P6:P12)>=4,504,IF(MAX(Q6:Q12)>=4,672,IF(MAX(R6:R12)>=4,"",""))))))))))) -> 6 | AB6: =IF($F6="","",IFERROR(VLOOKUP($F6,'04. Products & Services'!$B$5:$M$50,12,0),"")) | AC6: 7 days | AD6: {=IF(ISBLANK(AC6),"",_xlfn.LET( _xlpm.Num,--_xlfn.TEXTBEFORE(AC6," "), _xlpm.Unit,LOWER(_xlfn.TEXTAFTER(AC6," ")), _xlfn.SWITCH(_xlpm.Unit, "hour",_xlpm.Num, "hours",_xlpm.Num, "day",_xlpm.Num*24, "days",_xlpm.Num*24, "week",_xlpm.Num*24*7, "weeks",_xlpm.Num*24*7, "month",_xlpm.Num*24*(365.25/12), "months",_xlpm.Num*24*(365.25/12), "") ))} -> 168 | AF6: =TODAY() -> 46300 | AG6: =IF($AF6="","",DATE(YEAR($AF6)+1,MONTH($AF6),DAY($AF6))) -> 46665 | AH6: {=IF($B6="","",_xlfn.LET(_xlpm.ids,'15. BCM Risk Register'!$A$6:$A$65,_xlpm.links,'15. BCM Risk Register'!$I$6:$I$65,_xlpm.hit,ISNUMBER(SEARCH(","&$B6&",",","&SUBSTITUTE(_xlpm.links," ","")&",")),IFERROR(_xlfn.TEXTJOIN(", ",TRUE,_xlfn.UNIQUE(_xlfn._xlws.FILTER(_xlpm.ids,_xlpm.hit*(_xlpm.ids<>"")))),"Not Created")))} -> RA-001 | AI6: {=IF($B6="","",_xlfn.LET(_xlpm.ids,'15. BCM Risk Register'!$L$6:$L$65,_xlpm.links,'15. BCM Risk Register'!$I$6:$I$65,_xlpm.hit,ISNUMBER(SEARCH(","&$B6&",",","&SUBSTITUTE(_xlpm.links," ","")&",")),IFERROR(_xlfn.TEXTJOIN(", ",TRUE,_xlfn.UNIQUE(_xlfn._xlws.FILTER(_xlpm.ids,_xlpm.hit*(_xlpm.ids<>"")*(_xlpm.ids<>"Not Created")))),"Not Created")))} -> SS-030 | AJ6: {=IF($B6="","",_xlfn.LET(_xlpm.ids,'15. BCM Risk Register'!$K$6:$K$65,_xlpm.links,'15. BCM Risk Register'!$I$6:$I$65,_xlpm.hit,ISNUMBER(SEARCH(","&$B6&",",","&SUBSTITUTE(_xlpm.links," ","")&",")),IFERROR(_xlfn.TEXTJOIN(", ",TRUE,_xlfn.UNIQUE(_xlfn._xlws.FILTER(_xlpm.ids,_xlpm.hit*(_xlpm.ids<>"")*(_xlpm.ids<>"Not Created")))),"Not Created")))} -> RR-001
G7: ICT | I7: Operational | K7: 5 | T7: =IF($S$6="","",IF(COUNT(J7:R7)=0,"",IF(MAX(J7:R7)>3,$I7,""))) -> Operational
G8: Data / Info | I8: Product / Service Safety | K8: 1 | L8: 1 | M8: 1 | N8: 1 | O8: 1 | P8: 1 | Q8: 1 | R8: 1 | T8: =IF($S$6="","",IF(COUNT(J8:R8)=0,"",IF(MAX(J8:R8)>3,$I8,"")))
G9: 3rd Party | I9: Health, Safety & Environment | K9: 2 | L9: 2 | M9: 2 | N9: 2 | O9: 2 | P9: 2 | Q9: 2 | R9: 2 | T9: =IF($S$6="","",IF(COUNT(J9:R9)=0,"",IF(MAX(J9:R9)>3,$I9,"")))
G10: Equipment / Building / Utilities | I10: Regulatory & Compliance | K10: 3 | L10: 3 | M10: 3 | N10: 3 | O10: 3 | P10: 3 | Q10: 3 | R10: 3 | T10: =IF($S$6="","",IF(COUNT(J10:R10)=0,"",IF(MAX(J10:R10)>3,$I10,"")))
G11: Pre-Service | I11: Reputation | K11: 4 | L11: 4 | M11: 4 | N11: 4 | O11: 4 | P11: 4 | T11: =IF($S$6="","",IF(COUNT(J11:R11)=0,"",IF(MAX(J11:R11)>3,$I11,""))) -> Reputation
G12: Post-Service | I12: Information Technology | J12: 5 | K12: 5 | T12: =IF($S$6="","",IF(COUNT(J12:R12)=0,"",IF(MAX(J12:R12)>3,$I12,""))) -> Information Technology
A13: 2 | B13: =IF($E13="","","BIA-"&TEXT(2,"000")) | C13: =IFERROR(INDEX(BusinessUnits1,MATCH(A13,'04. Products & Services'!$N$6:$N$50,0)),"") | D13: =IFERROR(INDEX(DivisionSites,MATCH(A13,'04. Products & Services'!$N$6:$N$50,0)),"") | E13: =IFERROR(INDEX(ScopeNames,MATCH(A13,'04. Products & Services'!$N$6:$N$50,0)),"") | F13: =_xlfn.XLOOKUP(E13,'04. Products & Services'!$E$5:$E$50,'04. Products & Services'!$B$5:$B$50,"") | G13: People | I13: Financial | S13: =IF(COUNT(J13:R19)=0,"",MAX(J13:R19)) | T13: =IF($S$13="","",IF(COUNT(J13:R13)=0,"",IF(MAX(J13:R13)>3,$I13,""))) | U13: {=IF($E13="","",_xlfn.LET(_xlpm.matches,_xlfn._xlws.FILTER('04. Products & Services'!$J$6:$J$50,'04. Products & Services'!$E$6:$E$50=$E13,""),_xlpm.n,COUNTIF($E$6:$E13,$E13),_xlpm.v,IFERROR(INDEX(_xlpm.matches,_xlpm.n),""),IF(OR(_xlpm.v="",_xlpm.v=0),"",_xlpm.v)))} | W13: =IF($E13="","",IF(OR($U13="Yes",$V13="Yes"),"Yes",IF(AND($U13="No",$V13="No"),"No",IF(AND($U13="Under Evaluation",$V13="No"),"Under Evaluation","")))) | X13: =IF($E13="","",IFERROR(_xlfn.LET(_xlpm.v,INDEX('04. Products & Services'!$K$6:$K$50,MATCH($E13,ScopeNames,0)),IF(_xlpm.v="","",_xlpm.v)),"")) | AA13: =IF($E13="","",IF(COUNT(J13:R19)=0,"",IF(MAX(J13:J19)>=4,6,IF(MAX(K13:K19)>=4,18,IF(MAX(L13:L19)>=4,36,IF(MAX(M13:M19)>=4,72,IF(MAX(N13:N19)>=4,168,IF(MAX(O13:O19)>=4,336,IF(MAX(P13:P19)>=4,504,IF(MAX(Q13:Q19)>=4,672,IF(MAX(R13:R19)>=4,"",""))))))))))) | AB13: =IF($F13="","",IFERROR(VLOOKUP($F13,'04. Products & Services'!$B$5:$M$50,12,0),"")) | AD13: {=IF(ISBLANK(AC13),"",_xlfn.LET( _xlpm.Num,--_xlfn.TEXTBEFORE(AC13," "), _xlpm.Unit,LOWER(_xlfn.TEXTAFTER(AC13," ")), _xlfn.SWITCH(_xlpm.Unit, "hour",_xlpm.Num, "hours",_xlpm.Num, "day",_xlpm.Num*24, "days",_xlpm.Num*24, "week",_xlpm.Num*24*7, "weeks",_xlpm.Num*24*7, "month",_xlpm.Num*24*(365.25/12), "months",_xlpm.Num*24*(365.25/12), "") ))} | AG13: =IF($AF13="","",DATE(YEAR($AF13)+1,MONTH($AF13),DAY($AF13))) | AH13: {=IF($B13="","",_xlfn.LET(_xlpm.ids,'15. BCM Risk Register'!$A$6:$A$65,_xlpm.links,'15. BCM Risk Register'!$I$6:$I$65,_xlpm.hit,ISNUMBER(SEARCH(","&$B13&",",","&SUBSTITUTE(_xlpm.links," ","")&",")),IFERROR(_xlfn.TEXTJOIN(", ",TRUE,_xlfn.UNIQUE(_xlfn._xlws.FILTER(_xlpm.ids,_xlpm.hit*(_xlpm.ids<>"")))),"Not Created")))} | AI13: {=IF($B13="","",_xlfn.LET(_xlpm.ids,'15. BCM Risk Register'!$L$6:$L$65,_xlpm.links,'15. BCM Risk Register'!$I$6:$I$65,_xlpm.hit,ISNUMBER(SEARCH(","&$B13&",",","&SUBSTITUTE(_xlpm.links," ","")&",")),IFERROR(_xlfn.TEXTJOIN(", ",TRUE,_xlfn.UNIQUE(_xlfn._xlws.FILTER(_xlpm.ids,_xlpm.hit*(_xlpm.ids<>"")*(_xlpm.ids<>"Not Created")))),"Not Created")))} | AJ13: {=IF($B13="","",_xlfn.LET(_xlpm.ids,'15. BCM Risk Register'!$K$6:$K$65,_xlpm.links,'15. BCM Risk Register'!$I$6:$I$65,_xlpm.hit,ISNUMBER(SEARCH(","&$B13&",",","&SUBSTITUTE(_xlpm.links," ","")&",")),IFERROR(_xlfn.TEXTJOIN(", ",TRUE,_xlfn.UNIQUE(_xlfn._xlws.FILTER(_xlpm.ids,_xlpm.hit*(_xlpm.ids<>"")*(_xlpm.ids<>"Not Created")))),"Not Created")))}
G14: ICT | I14: Operational | T14: =IF($S$13="","",IF(COUNT(J14:R14)=0,"",IF(MAX(J14:R14)>3,$I14,"")))
G15: Data / Info | I15: Product / Service Safety | T15: =IF($S$13="","",IF(COUNT(J15:R15)=0,"",IF(MAX(J15:R15)>3,$I15,"")))
G16: 3rd Party | I16: Health, Safety & Environment | T16: =IF($S$13="","",IF(COUNT(J16:R16)=0,"",IF(MAX(J16:R16)>3,$I16,"")))
G17: Equipment / Building / Utilities | I17: Regulatory & Compliance | T17: =IF($S$13="","",IF(COUNT(J17:R17)=0,"",IF(MAX(J17:R17)>3,$I17,"")))
G18: Pre-Service | I18: Reputation | T18: =IF($S$13="","",IF(COUNT(J18:R18)=0,"",IF(MAX(J18:R18)>3,$I18,"")))
G19: Post-Service | I19: Information Technology | T19: =IF($S$13="","",IF(COUNT(J19:R19)=0,"",IF(MAX(J19:R19)>3,$I19,"")))
A20: 3 | B20: =IF($E20="","","BIA-"&TEXT(3,"000")) | C20: =IFERROR(INDEX(BusinessUnits1,MATCH(A20,'04. Products & Services'!$N$6:$N$50,0)),"") | D20: =IFERROR(INDEX(DivisionSites,MATCH(A20,'04. Products & Services'!$N$6:$N$50,0)),"") | E20: =IFERROR(INDEX(ScopeNames,MATCH(A20,'04. Products & Services'!$N$6:$N$50,0)),"") | F20: =_xlfn.XLOOKUP(E20,'04. Products & Services'!$E$5:$E$50,'04. Products & Services'!$B$5:$B$50,"") | G20: People | I20: Financial | S20: =IF(COUNT(J20:R26)=0,"",MAX(J20:R26)) | T20: =IF($S$20="","",IF(COUNT(J20:R20)=0,"",IF(MAX(J20:R20)>3,$I20,""))) | U20: {=IF($E20="","",_xlfn.LET(_xlpm.matches,_xlfn._xlws.FILTER('04. Products & Services'!$J$6:$J$50,'04. Products & Services'!$E$6:$E$50=$E20,""),_xlpm.n,COUNTIF($E$6:$E20,$E20),_xlpm.v,IFERROR(INDEX(_xlpm.matches,_xlpm.n),""),IF(OR(_xlpm.v="",_xlpm.v=0),"",_xlpm.v)))} | W20: =IF($E20="","",IF(OR($U20="Yes",$V20="Yes"),"Yes",IF(AND($U20="No",$V20="No"),"No",IF(AND($U20="Under Evaluation",$V20="No"),"Under Evaluation","")))) | X20: =IF($E20="","",IFERROR(_xlfn.LET(_xlpm.v,INDEX('04. Products & Services'!$K$6:$K$50,MATCH($E20,ScopeNames,0)),IF(_xlpm.v="","",_xlpm.v)),"")) | AA20: =IF($E20="","",IF(COUNT(J20:R26)=0,"",IF(MAX(J20:J26)>=4,6,IF(MAX(K20:K26)>=4,18,IF(MAX(L20:L26)>=4,36,IF(MAX(M20:M26)>=4,72,IF(MAX(N20:N26)>=4,168,IF(MAX(O20:O26)>=4,336,IF(MAX(P20:P26)>=4,504,IF(MAX(Q20:Q26)>=4,672,IF(MAX(R20:R26)>=4,"",""))))))))))) | AB20: =IF($F20="","",IFERROR(VLOOKUP($F20,'04. Products & Services'!$B$5:$M$50,12,0),"")) | AD20: {=IF(ISBLANK(AC20),"",_xlfn.LET( _xlpm.Num,--_xlfn.TEXTBEFORE(AC20," "), _xlpm.Unit,LOWER(_xlfn.TEXTAFTER(AC20," ")), _xlfn.SWITCH(_xlpm.Unit, "hour",_xlpm.Num, "hours",_xlpm.Num, "day",_xlpm.Num*24, "days",_xlpm.Num*24, "week",_xlpm.Num*24*7, "weeks",_xlpm.Num*24*7, "month",_xlpm.Num*24*(365.25/12), "months",_xlpm.Num*24*(365.25/12), "") ))} | AG20: =IF($AF20="","",DATE(YEAR($AF20)+1,MONTH($AF20),DAY($AF20))) | AH20: {=IF($B20="","",_xlfn.LET(_xlpm.ids,'15. BCM Risk Register'!$A$6:$A$65,_xlpm.links,'15. BCM Risk Register'!$I$6:$I$65,_xlpm.hit,ISNUMBER(SEARCH(","&$B20&",",","&SUBSTITUTE(_xlpm.links," ","")&",")),IFERROR(_xlfn.TEXTJOIN(", ",TRUE,_xlfn.UNIQUE(_xlfn._xlws.FILTER(_xlpm.ids,_xlpm.hit*(_xlpm.ids<>"")))),"Not Created")))} | AI20: {=IF($B20="","",_xlfn.LET(_xlpm.ids,'15. BCM Risk Register'!$L$6:$L$65,_xlpm.links,'15. BCM Risk Register'!$I$6:$I$65,_xlpm.hit,ISNUMBER(SEARCH(","&$B20&",",","&SUBSTITUTE(_xlpm.links," ","")&",")),IFERROR(_xlfn.TEXTJOIN(", ",TRUE,_xlfn.UNIQUE(_xlfn._xlws.FILTER(_xlpm.ids,_xlpm.hit*(_xlpm.ids<>"")*(_xlpm.ids<>"Not Created")))),"Not Created")))} | AJ20: {=IF($B20="","",_xlfn.LET(_xlpm.ids,'15. BCM Risk Register'!$K$6:$K$65,_xlpm.links,'15. BCM Risk Register'!$I$6:$I$65,_xlpm.hit,ISNUMBER(SEARCH(","&$B20&",",","&SUBSTITUTE(_xlpm.links," ","")&",")),IFERROR(_xlfn.TEXTJOIN(", ",TRUE,_xlfn.UNIQUE(_xlfn._xlws.FILTER(_xlpm.ids,_xlpm.hit*(_xlpm.ids<>"")*(_xlpm.ids<>"Not Created")))),"Not Created")))}
G21: ICT | I21: Operational | T21: =IF($S$20="","",IF(COUNT(J21:R21)=0,"",IF(MAX(J21:R21)>3,$I21,"")))
G22: Data / Info | I22: Product / Service Safety | T22: =IF($S$20="","",IF(COUNT(J22:R22)=0,"",IF(MAX(J22:R22)>3,$I22,"")))
G23: 3rd Party | I23: Health, Safety & Environment | T23: =IF($S$20="","",IF(COUNT(J23:R23)=0,"",IF(MAX(J23:R23)>3,$I23,"")))
G24: Equipment / Building / Utilities | I24: Regulatory & Compliance | T24: =IF($S$20="","",IF(COUNT(J24:R24)=0,"",IF(MAX(J24:R24)>3,$I24,"")))
G25: Pre-Service | I25: Reputation | T25: =IF($S$20="","",IF(COUNT(J25:R25)=0,"",IF(MAX(J25:R25)>3,$I25,"")))
G26: Post-Service | I26: Information Technology | T26: =IF($S$20="","",IF(COUNT(J26:R26)=0,"",IF(MAX(J26:R26)>3,$I26,"")))
A27: 4 | B27: =IF($E27="","","BIA-"&TEXT(4,"000")) | C27: =IFERROR(INDEX(BusinessUnits1,MATCH(A27,'04. Products & Services'!$N$6:$N$50,0)),"") | D27: =IFERROR(INDEX(DivisionSites,MATCH(A27,'04. Products & Services'!$N$6:$N$50,0)),"") | E27: =IFERROR(INDEX(ScopeNames,MATCH(A27,'04. Products & Services'!$N$6:$N$50,0)),"") | F27: =_xlfn.XLOOKUP(E27,'04. Products & Services'!$E$5:$E$50,'04. Products & Services'!$B$5:$B$50,"") | G27: People | I27: Financial | S27: =IF(COUNT(J27:R33)=0,"",MAX(J27:R33)) | T27: =IF($S$27="","",IF(COUNT(J27:R27)=0,"",IF(MAX(J27:R27)>3,$I27,""))) | U27: {=IF($E27="","",_xlfn.LET(_xlpm.matches,_xlfn._xlws.FILTER('04. Products & Services'!$J$6:$J$50,'04. Products & Services'!$E$6:$E$50=$E27,""),_xlpm.n,COUNTIF($E$6:$E27,$E27),_xlpm.v,IFERROR(INDEX(_xlpm.matches,_xlpm.n),""),IF(OR(_xlpm.v="",_xlpm.v=0),"",_xlpm.v)))} | W27: =IF($E27="","",IF(OR($U27="Yes",$V27="Yes"),"Yes",IF(AND($U27="No",$V27="No"),"No",IF(AND($U27="Under Evaluation",$V27="No"),"Under Evaluation","")))) | X27: =IF($E27="","",IFERROR(_xlfn.LET(_xlpm.v,INDEX('04. Products & Services'!$K$6:$K$50,MATCH($E27,ScopeNames,0)),IF(_xlpm.v="","",_xlpm.v)),"")) | AA27: =IF($E27="","",IF(COUNT(J27:R33)=0,"",IF(MAX(J27:J33)>=4,6,IF(MAX(K27:K33)>=4,18,IF(MAX(L27:L33)>=4,36,IF(MAX(M27:M33)>=4,72,IF(MAX(N27:N33)>=4,168,IF(MAX(O27:O33)>=4,336,IF(MAX(P27:P33)>=4,504,IF(MAX(Q27:Q33)>=4,672,IF(MAX(R27:R33)>=4,"",""))))))))))) | AB27: =IF($F27="","",IFERROR(VLOOKUP($F27,'04. Products & Services'!$B$5:$M$50,12,0),"")) | AD27: {=IF(ISBLANK(AC27),"",_xlfn.LET( _xlpm.Num,--_xlfn.TEXTBEFORE(AC27," "), _xlpm.Unit,LOWER(_xlfn.TEXTAFTER(AC27," ")), _xlfn.SWITCH(_xlpm.Unit, "hour",_xlpm.Num, "hours",_xlpm.Num, "day",_xlpm.Num*24, "days",_xlpm.Num*24, "week",_xlpm.Num*24*7, "weeks",_xlpm.Num*24*7, "month",_xlpm.Num*24*(365.25/12), "months",_xlpm.Num*24*(365.25/12), "") ))} | AG27: =IF($AF27="","",DATE(YEAR($AF27)+1,MONTH($AF27),DAY($AF27))) | AH27: {=IF($B27="","",_xlfn.LET(_xlpm.ids,'15. BCM Risk Register'!$A$6:$A$65,_xlpm.links,'15. BCM Risk Register'!$I$6:$I$65,_xlpm.hit,ISNUMBER(SEARCH(","&$B27&",",","&SUBSTITUTE(_xlpm.links," ","")&",")),IFERROR(_xlfn.TEXTJOIN(", ",TRUE,_xlfn.UNIQUE(_xlfn._xlws.FILTER(_xlpm.ids,_xlpm.hit*(_xlpm.ids<>"")))),"Not Created")))} | AI27: {=IF($B27="","",_xlfn.LET(_xlpm.ids,'15. BCM Risk Register'!$L$6:$L$65,_xlpm.links,'15. BCM Risk Register'!$I$6:$I$65,_xlpm.hit,ISNUMBER(SEARCH(","&$B27&",",","&SUBSTITUTE(_xlpm.links," ","")&",")),IFERROR(_xlfn.TEXTJOIN(", ",TRUE,_xlfn.UNIQUE(_xlfn._xlws.FILTER(_xlpm.ids,_xlpm.hit*(_xlpm.ids<>"")*(_xlpm.ids<>"Not Created")))),"Not Created")))} | AJ27: {=IF($B27="","",_xlfn.LET(_xlpm.ids,'15. BCM Risk Register'!$K$6:$K$65,_xlpm.links,'15. BCM Risk Register'!$I$6:$I$65,_xlpm.hit,ISNUMBER(SEARCH(","&$B27&",",","&SUBSTITUTE(_xlpm.links," ","")&",")),IFERROR(_xlfn.TEXTJOIN(", ",TRUE,_xlfn.UNIQUE(_xlfn._xlws.FILTER(_xlpm.ids,_xlpm.hit*(_xlpm.ids<>"")*(_xlpm.ids<>"Not Created")))),"Not Created")))}
G28: ICT | I28: Operational | T28: =IF($S$27="","",IF(COUNT(J28:R28)=0,"",IF(MAX(J28:R28)>3,$I28,"")))
G29: Data / Info | I29: Product / Service Safety | T29: =IF($S$27="","",IF(COUNT(J29:R29)=0,"",IF(MAX(J29:R29)>3,$I29,"")))
G30: 3rd Party | I30: Health, Safety & Environment | T30: =IF($S$27="","",IF(COUNT(J30:R30)=0,"",IF(MAX(J30:R30)>3,$I30,"")))
G31: Equipment / Building / Utilities | I31: Regulatory & Compliance | T31: =IF($S$27="","",IF(COUNT(J31:R31)=0,"",IF(MAX(J31:R31)>3,$I31,"")))
G32: Pre-Service | I32: Reputation | T32: =IF($S$27="","",IF(COUNT(J32:R32)=0,"",IF(MAX(J32:R32)>3,$I32,"")))
G33: Post-Service | I33: Information Technology | T33: =IF($S$27="","",IF(COUNT(J33:R33)=0,"",IF(MAX(J33:R33)>3,$I33,"")))
A34: 5 | B34: =IF($E34="","","BIA-"&TEXT(5,"000")) | C34: =IFERROR(INDEX(BusinessUnits1,MATCH(A34,'04. Products & Services'!$N$6:$N$50,0)),"") | D34: =IFERROR(INDEX(DivisionSites,MATCH(A34,'04. Products & Services'!$N$6:$N$50,0)),"") | E34: =IFERROR(INDEX(ScopeNames,MATCH(A34,'04. Products & Services'!$N$6:$N$50,0)),"") | F34: =_xlfn.XLOOKUP(E34,'04. Products & Services'!$E$5:$E$50,'04. Products & Services'!$B$5:$B$50,"") | G34: People | I34: Financial | S34: =IF(COUNT(J34:R40)=0,"",MAX(J34:R40)) | T34: =IF($S$34="","",IF(COUNT(J34:R34)=0,"",IF(MAX(J34:R34)>3,$I34,""))) | U34: {=IF($E34="","",_xlfn.LET(_xlpm.matches,_xlfn._xlws.FILTER('04. Products & Services'!$J$6:$J$50,'04. Products & Services'!$E$6:$E$50=$E34,""),_xlpm.n,COUNTIF($E$6:$E34,$E34),_xlpm.v,IFERROR(INDEX(_xlpm.matches,_xlpm.n),""),IF(OR(_xlpm.v="",_xlpm.v=0),"",_xlpm.v)))} | W34: =IF($E34="","",IF(OR($U34="Yes",$V34="Yes"),"Yes",IF(AND($U34="No",$V34="No"),"No",IF(AND($U34="Under Evaluation",$V34="No"),"Under Evaluation","")))) | X34: =IF($E34="","",IFERROR(_xlfn.LET(_xlpm.v,INDEX('04. Products & Services'!$K$6:$K$50,MATCH($E34,ScopeNames,0)),IF(_xlpm.v="","",_xlpm.v)),"")) | AA34: =IF($E34="","",IF(COUNT(J34:R40)=0,"",IF(MAX(J34:J40)>=4,6,IF(MAX(K34:K40)>=4,18,IF(MAX(L34:L40)>=4,36,IF(MAX(M34:M40)>=4,72,IF(MAX(N34:N40)>=4,168,IF(MAX(O34:O40)>=4,336,IF(MAX(P34:P40)>=4,504,IF(MAX(Q34:Q40)>=4,672,IF(MAX(R34:R40)>=4,"",""))))))))))) | AB34: =IF($F34="","",IFERROR(VLOOKUP($F34,'04. Products & Services'!$B$5:$M$50,12,0),"")) | AD34: {=IF(ISBLANK(AC34),"",_xlfn.LET( _xlpm.Num,--_xlfn.TEXTBEFORE(AC34," "), _xlpm.Unit,LOWER(_xlfn.TEXTAFTER(AC34," ")), _xlfn.SWITCH(_xlpm.Unit, "hour",_xlpm.Num, "hours",_xlpm.Num, "day",_xlpm.Num*24, "days",_xlpm.Num*24, "week",_xlpm.Num*24*7, "weeks",_xlpm.Num*24*7, "month",_xlpm.Num*24*(365.25/12), "months",_xlpm.Num*24*(365.25/12), "") ))} | AG34: =IF($AF34="","",DATE(YEAR($AF34)+1,MONTH($AF34),DAY($AF34))) | AH34: {=IF($B34="","",_xlfn.LET(_xlpm.ids,'15. BCM Risk Register'!$A$6:$A$65,_xlpm.links,'15. BCM Risk Register'!$I$6:$I$65,_xlpm.hit,ISNUMBER(SEARCH(","&$B34&",",","&SUBSTITUTE(_xlpm.links," ","")&",")),IFERROR(_xlfn.TEXTJOIN(", ",TRUE,_xlfn.UNIQUE(_xlfn._xlws.FILTER(_xlpm.ids,_xlpm.hit*(_xlpm.ids<>"")))),"Not Created")))} | AI34: {=IF($B34="","",_xlfn.LET(_xlpm.ids,'15. BCM Risk Register'!$L$6:$L$65,_xlpm.links,'15. BCM Risk Register'!$I$6:$I$65,_xlpm.hit,ISNUMBER(SEARCH(","&$B34&",",","&SUBSTITUTE(_xlpm.links," ","")&",")),IFERROR(_xlfn.TEXTJOIN(", ",TRUE,_xlfn.UNIQUE(_xlfn._xlws.FILTER(_xlpm.ids,_xlpm.hit*(_xlpm.ids<>"")*(_xlpm.ids<>"Not Created")))),"Not Created")))} | AJ34: {=IF($B34="","",_xlfn.LET(_xlpm.ids,'15. BCM Risk Register'!$K$6:$K$65,_xlpm.links,'15. BCM Risk Register'!$I$6:$I$65,_xlpm.hit,ISNUMBER(SEARCH(","&$B34&",",","&SUBSTITUTE(_xlpm.links," ","")&",")),IFERROR(_xlfn.TEXTJOIN(", ",TRUE,_xlfn.UNIQUE(_xlfn._xlws.FILTER(_xlpm.ids,_xlpm.hit*(_xlpm.ids<>"")*(_xlpm.ids<>"Not Created")))),"Not Created")))}
G35: ICT | I35: Operational | T35: =IF($S$34="","",IF(COUNT(J35:R35)=0,"",IF(MAX(J35:R35)>3,$I35,"")))
G36: Data / Info | I36: Product / Service Safety | T36: =IF($S$34="","",IF(COUNT(J36:R36)=0,"",IF(MAX(J36:R36)>3,$I36,"")))
G37: 3rd Party | I37: Health, Safety & Environment | T37: =IF($S$34="","",IF(COUNT(J37:R37)=0,"",IF(MAX(J37:R37)>3,$I37,"")))
G38: Equipment / Building / Utilities | I38: Regulatory & Compliance | T38: =IF($S$34="","",IF(COUNT(J38:R38)=0,"",IF(MAX(J38:R38)>3,$I38,"")))
G39: Pre-Service | I39: Reputation | T39: =IF($S$34="","",IF(COUNT(J39:R39)=0,"",IF(MAX(J39:R39)>3,$I39,"")))
G40: Post-Service | I40: Information Technology | T40: =IF($S$34="","",IF(COUNT(J40:R40)=0,"",IF(MAX(J40:R40)>3,$I40,"")))
A41: 6 | B41: =IF($E41="","","BIA-"&TEXT(6,"000")) | C41: =IFERROR(INDEX(BusinessUnits1,MATCH(A41,'04. Products & Services'!$N$6:$N$50,0)),"") | D41: =IFERROR(INDEX(DivisionSites,MATCH(A41,'04. Products & Services'!$N$6:$N$50,0)),"") | E41: =IFERROR(INDEX(ScopeNames,MATCH(A41,'04. Products & Services'!$N$6:$N$50,0)),"") | F41: =_xlfn.XLOOKUP(E41,'04. Products & Services'!$E$5:$E$50,'04. Products & Services'!$B$5:$B$50,"") | G41: People | I41: Financial | S41: =IF(COUNT(J41:R47)=0,"",MAX(J41:R47)) | T41: =IF($S$41="","",IF(COUNT(J41:R41)=0,"",IF(MAX(J41:R41)>3,$I41,""))) | U41: {=IF($E41="","",_xlfn.LET(_xlpm.matches,_xlfn._xlws.FILTER('04. Products & Services'!$J$6:$J$50,'04. Products & Services'!$E$6:$E$50=$E41,""),_xlpm.n,COUNTIF($E$6:$E41,$E41),_xlpm.v,IFERROR(INDEX(_xlpm.matches,_xlpm.n),""),IF(OR(_xlpm.v="",_xlpm.v=0),"",_xlpm.v)))} | W41: =IF($E41="","",IF(OR($U41="Yes",$V41="Yes"),"Yes",IF(AND($U41="No",$V41="No"),"No",IF(AND($U41="Under Evaluation",$V41="No"),"Under Evaluation","")))) | X41: =IF($E41="","",IFERROR(_xlfn.LET(_xlpm.v,INDEX('04. Products & Services'!$K$6:$K$50,MATCH($E41,ScopeNames,0)),IF(_xlpm.v="","",_xlpm.v)),"")) | AA41: =IF($E41="","",IF(COUNT(J41:R47)=0,"",IF(MAX(J41:J47)>=4,6,IF(MAX(K41:K47)>=4,18,IF(MAX(L41:L47)>=4,36,IF(MAX(M41:M47)>=4,72,IF(MAX(N41:N47)>=4,168,IF(MAX(O41:O47)>=4,336,IF(MAX(P41:P47)>=4,504,IF(MAX(Q41:Q47)>=4,672,IF(MAX(R41:R47)>=4,"",""))))))))))) | AB41: =IF($F41="","",IFERROR(VLOOKUP($F41,'04. Products & Services'!$B$5:$M$50,12,0),"")) | AD41: {=IF(ISBLANK(AC41),"",_xlfn.LET( _xlpm.Num,--_xlfn.TEXTBEFORE(AC41," "), _xlpm.Unit,LOWER(_xlfn.TEXTAFTER(AC41," ")), _xlfn.SWITCH(_xlpm.Unit, "hour",_xlpm.Num, "hours",_xlpm.Num, "day",_xlpm.Num*24, "days",_xlpm.Num*24, "week",_xlpm.Num*24*7, "weeks",_xlpm.Num*24*7, "month",_xlpm.Num*24*(365.25/12), "months",_xlpm.Num*24*(365.25/12), "") ))} | AG41: =IF($AF41="","",DATE(YEAR($AF41)+1,MONTH($AF41),DAY($AF41))) | AH41: {=IF($B41="","",_xlfn.LET(_xlpm.ids,'15. BCM Risk Register'!$A$6:$A$65,_xlpm.links,'15. BCM Risk Register'!$I$6:$I$65,_xlpm.hit,ISNUMBER(SEARCH(","&$B41&",",","&SUBSTITUTE(_xlpm.links," ","")&",")),IFERROR(_xlfn.TEXTJOIN(", ",TRUE,_xlfn.UNIQUE(_xlfn._xlws.FILTER(_xlpm.ids,_xlpm.hit*(_xlpm.ids<>"")))),"Not Created")))} | AI41: {=IF($B41="","",_xlfn.LET(_xlpm.ids,'15. BCM Risk Register'!$L$6:$L$65,_xlpm.links,'15. BCM Risk Register'!$I$6:$I$65,_xlpm.hit,ISNUMBER(SEARCH(","&$B41&",",","&SUBSTITUTE(_xlpm.links," ","")&",")),IFERROR(_xlfn.TEXTJOIN(", ",TRUE,_xlfn.UNIQUE(_xlfn._xlws.FILTER(_xlpm.ids,_xlpm.hit*(_xlpm.ids<>"")*(_xlpm.ids<>"Not Created")))),"Not Created")))} | AJ41: {=IF($B41="","",_xlfn.LET(_xlpm.ids,'15. BCM Risk Register'!$K$6:$K$65,_xlpm.links,'15. BCM Risk Register'!$I$6:$I$65,_xlpm.hit,ISNUMBER(SEARCH(","&$B41&",",","&SUBSTITUTE(_xlpm.links," ","")&",")),IFERROR(_xlfn.TEXTJOIN(", ",TRUE,_xlfn.UNIQUE(_xlfn._xlws.FILTER(_xlpm.ids,_xlpm.hit*(_xlpm.ids<>"")*(_xlpm.ids<>"Not Created")))),"Not Created")))}
...

Sheet 08. Dependency Register
A1: Step 2b - Dependency Register
A2: one row per dependency | ISO 22301: 8.2.2 Dependencies & supporting resources
A4: No. | B4: Dep ID | C4: BIA # (select) | D4: Product / Service (auto) | E4: Product / Service ID | F4: Category (select) | G4: Sub category (For ICT and Equipment) | H4: ICT/ Equipment details | I4: Dependency Name | J4: Description / Detail | K4: SPOF? (Y/N) | L4: Owner | M4: Remarks
A5: 1 | B5: =IF($I5="","","DEP-"&TEXT($A5,"000")) | C5: BIA-001 | D5: =IF($C5="","",IFERROR(_xlfn.XLOOKUP($C5,'07. BIA'!$B$6:$B$285,'07. BIA'!$E$6:$E$285,""),"")) -> cb | E5: =IF($C5="","",IFERROR(_xlfn.XLOOKUP($C5,'07. BIA'!$B$6:$B$285,'07. BIA'!$F$6:$F$285,""),"")) -> PS-001 | F5: People
A6: 2 | B6: =IF($I6="","","DEP-"&TEXT($A6,"000")) | D6: =IF($C6="","",IFERROR(_xlfn.XLOOKUP($C6,'07. BIA'!$B$6:$B$285,'07. BIA'!$E$6:$E$285,""),"")) | E6: =IF($C6="","",IFERROR(_xlfn.XLOOKUP($C6,'07. BIA'!$B$6:$B$285,'07. BIA'!$F$6:$F$285,""),""))
A7: 3 | B7: =IF($I7="","","DEP-"&TEXT($A7,"000")) | D7: =IF($C7="","",IFERROR(_xlfn.XLOOKUP($C7,'07. BIA'!$B$6:$B$285,'07. BIA'!$E$6:$E$285,""),"")) | E7: =IF($C7="","",IFERROR(_xlfn.XLOOKUP($C7,'07. BIA'!$B$6:$B$285,'07. BIA'!$F$6:$F$285,""),""))
A8: 4 | B8: =IF($I8="","","DEP-"&TEXT($A8,"000")) | D8: =IF($C8="","",IFERROR(_xlfn.XLOOKUP($C8,'07. BIA'!$B$6:$B$285,'07. BIA'!$E$6:$E$285,""),"")) | E8: =IF($C8="","",IFERROR(_xlfn.XLOOKUP($C8,'07. BIA'!$B$6:$B$285,'07. BIA'!$F$6:$F$285,""),""))
A9: 5 | B9: =IF($I9="","","DEP-"&TEXT($A9,"000")) | D9: =IF($C9="","",IFERROR(_xlfn.XLOOKUP($C9,'07. BIA'!$B$6:$B$285,'07. BIA'!$E$6:$E$285,""),"")) | E9: =IF($C9="","",IFERROR(_xlfn.XLOOKUP($C9,'07. BIA'!$B$6:$B$285,'07. BIA'!$F$6:$F$285,""),""))
A10: 6 | B10: =IF($I10="","","DEP-"&TEXT($A10,"000")) | D10: =IF($C10="","",IFERROR(_xlfn.XLOOKUP($C10,'07. BIA'!$B$6:$B$285,'07. BIA'!$E$6:$E$285,""),"")) | E10: =IF($C10="","",IFERROR(_xlfn.XLOOKUP($C10,'07. BIA'!$B$6:$B$285,'07. BIA'!$F$6:$F$285,""),""))
A11: 7 | B11: =IF($I11="","","DEP-"&TEXT($A11,"000")) | D11: =IF($C11="","",IFERROR(_xlfn.XLOOKUP($C11,'07. BIA'!$B$6:$B$285,'07. BIA'!$E$6:$E$285,""),"")) | E11: =IF($C11="","",IFERROR(_xlfn.XLOOKUP($C11,'07. BIA'!$B$6:$B$285,'07. BIA'!$F$6:$F$285,""),""))
A12: 8 | B12: =IF($I12="","","DEP-"&TEXT($A12,"000")) | D12: =IF($C12="","",IFERROR(_xlfn.XLOOKUP($C12,'07. BIA'!$B$6:$B$285,'07. BIA'!$E$6:$E$285,""),"")) | E12: =IF($C12="","",IFERROR(_xlfn.XLOOKUP($C12,'07. BIA'!$B$6:$B$285,'07. BIA'!$F$6:$F$285,""),""))
A13: 9 | B13: =IF($I13="","","DEP-"&TEXT($A13,"000")) | D13: =IF($C13="","",IFERROR(_xlfn.XLOOKUP($C13,'07. BIA'!$B$6:$B$285,'07. BIA'!$E$6:$E$285,""),"")) | E13: =IF($C13="","",IFERROR(_xlfn.XLOOKUP($C13,'07. BIA'!$B$6:$B$285,'07. BIA'!$F$6:$F$285,""),""))
A14: 10 | B14: =IF($I14="","","DEP-"&TEXT($A14,"000")) | D14: =IF($C14="","",IFERROR(_xlfn.XLOOKUP($C14,'07. BIA'!$B$6:$B$285,'07. BIA'!$E$6:$E$285,""),"")) | E14: =IF($C14="","",IFERROR(_xlfn.XLOOKUP($C14,'07. BIA'!$B$6:$B$285,'07. BIA'!$F$6:$F$285,""),""))
A15: 11 | B15: =IF($I15="","","DEP-"&TEXT($A15,"000")) | D15: =IF($C15="","",IFERROR(_xlfn.XLOOKUP($C15,'07. BIA'!$B$6:$B$285,'07. BIA'!$E$6:$E$285,""),"")) | E15: =IF($C15="","",IFERROR(_xlfn.XLOOKUP($C15,'07. BIA'!$B$6:$B$285,'07. BIA'!$F$6:$F$285,""),""))
A16: 12 | B16: =IF($I16="","","DEP-"&TEXT($A16,"000")) | D16: =IF($C16="","",IFERROR(_xlfn.XLOOKUP($C16,'07. BIA'!$B$6:$B$285,'07. BIA'!$E$6:$E$285,""),"")) | E16: =IF($C16="","",IFERROR(_xlfn.XLOOKUP($C16,'07. BIA'!$B$6:$B$285,'07. BIA'!$F$6:$F$285,""),""))
A17: 13 | B17: =IF($I17="","","DEP-"&TEXT($A17,"000")) | D17: =IF($C17="","",IFERROR(_xlfn.XLOOKUP($C17,'07. BIA'!$B$6:$B$285,'07. BIA'!$E$6:$E$285,""),"")) | E17: =IF($C17="","",IFERROR(_xlfn.XLOOKUP($C17,'07. BIA'!$B$6:$B$285,'07. BIA'!$F$6:$F$285,""),""))
