Workbook
Name BIAIDs: '07. BIA'!$B$6:$B$285
Name BusinessUnit: '03. Business Unit Profile'!$T$138:$T$182
Name BusinessUnits: '10. Risk Assessment'!$C$5
Name BusinessUnits1: '04. Products & Services'!$C$5:$C$49
Name CAPA_BIARefs: '07. BIA'!$B$6:$B$285
Name CAPA_DepRefs: '08. Dependency Register'!$B$5:$B$204
Name CAPA_DocRefs: '10. Risk Assessment'!$Y$5:$Y$34
Name CAPA_DRRefs: '13. IT DR Register'!$B$5:$B$204
Name CAPA_RiskRefs: '10. Risk Assessment'!$B$5:$B$34
Name CAPA_RRRefs: '14. Recovery & Response'!$B$5:$B$104
Name DC_1: '09. Risk Assumption Map'!$C$4:$I$4
Name DependencyBIAIDs: '08. Dependency Register'!$C$5:$C$204
Name DivisionSite: '03. Business Unit Profile'!$U$138:$U$182
Name DivisionSites: '04. Products & Services'!$D$5:$D$49
Name DurationUnits: '03. Business Unit Profile'!$AA$138:$AB$141
Name E_1: '06. Application & Equipment'!$I$9
Name E_E: '06. Application & Equipment'!$I$10:$I$34
Name I_A: '06. Application & Equipment'!$G$10:$G$34
Name I_S: '06. Application & Equipment'!$H$10:$H$34
Name ICT_0: '06. Application & Equipment'!$A$10
Name ICT_1: '06. Application & Equipment'!$G$9
Name ICT_List: '06. Application & Equipment'!$G$9:$H$9
Name lstChainCrit: '03. Business Unit Profile'!$K$138:$K$141
Name lstCorpCrit: '03. Business Unit Profile'!$J$138:$J$140
Name lstDepCat: '03. Business Unit Profile'!$I$138:$I$144
Name lstDRStrategy: '03. Business Unit Profile'!$O$138:$O$143
Name lstISOStatus: '03. Business Unit Profile'!$V$138:$V$141
Name lstReqCat: '03. Business Unit Profile'!$R$138:$R$143
Name lstScore: '03. Business Unit Profile'!$H$138:$H$143
Name lstSPOF: '03. Business Unit Profile'!$Q$138:$Q$139
Name lstStatus: '03. Business Unit Profile'!$L$138:$L$141
Name lstStrategy: '03. Business Unit Profile'!$M$138:$M$144
Name lstTestResult: '03. Business Unit Profile'!$N$138:$N$140
Name lstYN: '03. Business Unit Profile'!$F$138:$F$139
Name lstYPN: '03. Business Unit Profile'!$G$138:$G$140
Name MTPDMap: '03. Business Unit Profile'!$X$138:$Y$146
Name ProcessProductCodes: '05. Processes & Activities'!$B$5:$B$211
Name PS_ID: '04. Products & Services'!$B$5:$B$49
Name RA_ID: '10. Risk Assessment'!$B$5:$B$34
Name RequirementStrategyIDs: '12. Requirements Register'!$C$5:$C$304
Name RiskIDs: '10. Risk Assessment'!$B$5:$B$34
Name RR_BIAs: '14. Recovery & Response'!$T$5:$T$104
Name RR_ID: '14. Recovery & Response'!$B$5:$B$104
Name RR_Risk: '14. Recovery & Response'!$S$5:$S$104
Name RR_SS: '14. Recovery & Response'!$C$5:$C$104
Name RR_Status: '14. Recovery & Response'!$P$5:$P$104
Name S_1: '06. Application & Equipment'!$C$11
Name ScopeNames: '04. Products & Services'!$E$5:$E$49
Name SS_BIAs: '11. Strategies & Solutions'!$X$5:$X$64
Name SS_Due: '11. Strategies & Solutions'!$R$5:$R$64
Name SS_ID: '11. Strategies & Solutions'!$C$5:$C$64
Name SS_Risk: '11. Strategies & Solutions'!$B$5:$B$64
Name SS_Status: '11. Strategies & Solutions'!$T$5:$T$64
Name SSIDs: '11. Strategies & Solutions'!$C$5:$C$64
Name StrategyRiskIDs: '11. Strategies & Solutions'!$B$5:$B$64

Sheet 02. Dashboard
A1: BCM Programme Dashboard - Organization
A4: Coverage | D4: Risk & Readiness | G4: Governance & Compliance
A5: P&S in scope | B5: =COUNTIF('04. Products & Services'!$I$5:$I$49,"Yes") | D5: Risks assessed | E5: =COUNTIF(INDEX(RiskAssessment[],0,2),"RA-*") | G5: BCP rows (RR plan) | H5: =COUNTIF('14. Recovery & Response'!$C$5:$C$104,"SS-*")
A6: BIAs completed | B6: {=SUMPRODUCT(--('07. BIA'!$B$6:$B$285<>""),--ISNUMBER('07. BIA'!$AF$6:$AF$285))} | D6: Critical / Significant risks | E6: =COUNTIF('10. Risk Assessment'!$P$5:$P$34,"Critical")+COUNTIF('10. Risk Assessment'!$P$5:$P$34,"Significant") | G6: Exercises done / overdue | H6: =COUNT('14. Recovery & Response'!$M$5:$M$104)&" / "&COUNTIF('14. Recovery & Response'!$P$5:$P$104,"Overdue")
A7: Critical P&S (final) | B7: =COUNTIF('07. BIA'!$W$6:$W$285,"Yes") | D7: Priority 1-2 risks (BCP) | E7: =COUNTIF('10. Risk Assessment'!$Q$5:$Q$34,1)+COUNTIF('10. Risk Assessment'!$Q$5:$Q$34,2) | G7: DR systems / tested-current | H7: =COUNTIF('13. IT DR Register'!$B$5:$B$204,"DR-*")&" / "&COUNTIF('13. IT DR Register'!$Q$5:$Q$204,"Tested & Current")
A8: P&S-risk associations | B8: {=_xlfn.LET(_xlpm.x,INDEX(RiskAssessment[],0,6),SUMPRODUCT(--(_xlpm.x<>""),LEN(_xlpm.x)-LEN(SUBSTITUTE(_xlpm.x,",",""))+1))} | D8: Solutions defined / overdue | E8: =COUNTIF('11. Strategies & Solutions'!$C$5:$C$64,"SS-*")&" / "&COUNTIF('11. Strategies & Solutions'!$T$5:$T$64,"Overdue") | G8: Duplicate S&S mappings | H8: =COUNTIF('11. Strategies & Solutions'!$U$5:$U$64,"DUPLICATE")
A9: Dependencies registered | B9: =COUNTIF('08. Dependency Register'!$B$5:$B$204,"DEP-*") | D9: Requirement rows (5b) | E9: =COUNTIF('12. Requirements Register'!$B$5:$B$304,"REQ-*")
A10: BIA reviews overdue | B10: =SUMPRODUCT(--('07. BIA'!$AG$6:$AG$285<>"")*('07. BIA'!$AG$6:$AG$285<TODAY()))
A13: Corrective Action & Improvement
A14: Open CAPAs | B14: =COUNTIFS('16. CAPA Register'!$B$6:$B$105,"CAPA-*",'16. CAPA Register'!$M$6:$M$105,"<>Closed",'16. CAPA Register'!$M$6:$M$105,"<>Cancelled") | D14: Overdue CAPAs | E14: =COUNTIF('16. CAPA Register'!$T$6:$T$105,"Overdue") | G14: Effectiveness pending | H14: =COUNTIFS('16. CAPA Register'!$M$6:$M$105,"Pending Verification")+COUNTIFS('16. CAPA Register'!$M$6:$M$105,"Closed",'16. CAPA Register'!$Q$6:$Q$105,"Pending")
A15: Critical / High open | B15: =COUNTIFS('16. CAPA Register'!$M$6:$M$105,"<>Closed",'16. CAPA Register'!$M$6:$M$105,"<>Cancelled",'16. CAPA Register'!$G$6:$G$105,"Critical")+COUNTIFS('16. CAPA Register'!$M$6:$M$105,"<>Closed",'16. CAPA Register'!$M$6:$M$105,"<>Cancelled",'16. CAPA Register'!$G$6:$G$105,"High")

Sheet 03. Business Unit Profile
A1: Business Unit Profile - BCM Implementation Scope
A4: Section 1 - Organization Identity
A5: Organization Legal Name
A6: Business Unit Name
A7: Business Unit Code / ID
A8: Parent Division
A9: Headquarters Location
A10: Operating Locations (list)
A11: Date Established
A12: Number of Employees (BU)
A13: Industry Sector
A14: Primary Business Activities
A16: Section 2 - Leadership & Governance
A17: Field | B17: Name | C17: Title | D17: Contact
A27: Section 3 - Internal Context
A28: Mission Statement
A29: Vision Statement
A30: Strategic Objectives (BU)
A31: Key Products / Services
A32: Annual Revenue (local currency)
A33: Operating Hours
A34: Peak Seasons / Periods
A35: Organizational Structure
A37: Section 4 - External Context
A38: Primary Regulators
A39: Market Position
... A48: Section 5 - Climate Relevance for BCMS Context and Interested Parties
A49: Climate prompt | B49: Assessment / response
A50: Is climate change a relevant external or internal issue for the BCMS? Record the rationale.
A51: Which interested parties have climate-related requirements or expectations relevant to continuity?
A52: Which products, sites, utilities, logistics routes, suppliers or ICT services have climate-sensitive dependencies?
A53: Which acute or chronic climate-related disruption scenarios should be assessed?
A54: Which continuity strategies or actions address material climate-related risks and dependencies?
A56: Section 6 - Interested Parties & Requirements
A57: Interested Party | B57: Requirements / Expectations | C57: How Addressed | D57: Priority
A58: Shareholders / Board
A59: Customers (B2B)
A60: Consumers (End Users)
A61: Employees
A62: Suppliers / Vendors
...

Sheet 04. Products & Services
A1: Scope: Organization Products & Services
A4: No. | B4: P&S ID | C4: Business Unit | D4: Division / Site | E4: Product / Service | F4: Sub-Category | G4: Owner | H4: EVP | I4: In Scope (Y/N) | J4: Corporate BIA Critical | K4: Corporate MBCO (if provided) | L4: Corporate MTPD (if provided) | M4: Corporate MTPD (hours) | N4: BIA Order | O4: BU BIA MTPD | P4: Business unit list order | Q4: Division list order
A5: 1 | B5: =IF($E5="","","PS-"&TEXT($A5,"000")) | M5: =IF(L5="","",IF(ISNUMBER(L5),L5,IFERROR(VALUE(LEFT(TRIM(L5),FIND(" ",TRIM(L5))-1))*VLOOKUP(LEFT(LOWER(TRIM(MID(TRIM(L5),FIND(" ",TRIM(L5))+1,99))),3),DurationUnits,2,FALSE),""))) | N5: =IF($I5<>"Yes","",IF($A5="","",COUNTIFS($A$5:$A$49,"<"&$A5,$I$5:$I$49,"Yes")+1)) | O5: =IF($E5="","",IFERROR(IF(INDEX('07. BIA'!$AA$6:$AA$285,MATCH($E5,'07. BIA'!$E$6:$E$285,0))="","",INDEX('07. BIA'!$AA$6:$AA$285,MATCH($E5,'07. BIA'!$E$6:$E$285,0))),"")) | P5: =IF(C5="","",IF(COUNTIF($C$5:C5,C5)=1,MAX($P$4:P4)+1,"")) | Q5: =IF(D5="","",IF(COUNTIF($D$5:D5,D5)=1,MAX($Q$4:Q4)+1,""))
A6: 2 | B6: =IF($E6="","","PS-"&TEXT($A6,"000")) | M6: =IF(L6="","",IF(ISNUMBER(L6),L6,IFERROR(VALUE(LEFT(TRIM(L6),FIND(" ",TRIM(L6))-1))*VLOOKUP(LEFT(LOWER(TRIM(MID(TRIM(L6),FIND(" ",TRIM(L6))+1,99))),3),DurationUnits,2,FALSE),""))) | N6: =IF($I6<>"Yes","",IF($A6="","",COUNTIFS($A$5:$A$49,"<"&$A6,$I$5:$I$49,"Yes")+1)) | O6: =IF($E6="","",IFERROR(IF(INDEX('07. BIA'!$AA$6:$AA$285,MATCH($E6,'07. BIA'!$E$6:$E$285,0))="","",INDEX('07. BIA'!$AA$6:$AA$285,MATCH($E6,'07. BIA'!$E$6:$E$285,0))),"")) | P6: =IF(C6="","",IF(COUNTIF($C$5:C6,C6)=1,MAX($P$4:P5)+1,"")) | Q6: =IF(D6="","",IF(COUNTIF($D$5:D6,D6)=1,MAX($Q$4:Q5)+1,""))
A7: 3 | B7: =IF($E7="","","PS-"&TEXT($A7,"000")) | M7: =IF(L7="","",IF(ISNUMBER(L7),L7,IFERROR(VALUE(LEFT(TRIM(L7),FIND(" ",TRIM(L7))-1))*VLOOKUP(LEFT(LOWER(TRIM(MID(TRIM(L7),FIND(" ",TRIM(L7))+1,99))),3),DurationUnits,2,FALSE),""))) | N7: =IF($I7<>"Yes","",IF($A7="","",COUNTIFS($A$5:$A$49,"<"&$A7,$I$5:$I$49,"Yes")+1)) | O7: =IF($E7="","",IFERROR(IF(INDEX('07. BIA'!$AA$6:$AA$285,MATCH($E7,'07. BIA'!$E$6:$E$285,0))="","",INDEX('07. BIA'!$AA$6:$AA$285,MATCH($E7,'07. BIA'!$E$6:$E$285,0))),"")) | P7: =IF(C7="","",IF(COUNTIF($C$5:C7,C7)=1,MAX($P$4:P6)+1,"")) | Q7: =IF(D7="","",IF(COUNTIF($D$5:D7,D7)=1,MAX($Q$4:Q6)+1,""))
A8: 4 | B8: =IF($E8="","","PS-"&TEXT($A8,"000")) | M8: =IF(L8="","",IF(ISNUMBER(L8),L8,IFERROR(VALUE(LEFT(TRIM(L8),FIND(" ",TRIM(L8))-1))*VLOOKUP(LEFT(LOWER(TRIM(MID(TRIM(L8),FIND(" ",TRIM(L8))+1,99))),3),DurationUnits,2,FALSE),""))) | N8: =IF($I8<>"Yes","",IF($A8="","",COUNTIFS($A$5:$A$49,"<"&$A8,$I$5:$I$49,"Yes")+1)) | O8: =IF($E8="","",IFERROR(IF(INDEX('07. BIA'!$AA$6:$AA$285,MATCH($E8,'07. BIA'!$E$6:$E$285,0))="","",INDEX('07. BIA'!$AA$6:$AA$285,MATCH($E8,'07. BIA'!$E$6:$E$285,0))),"")) | P8: =IF(C8="","",IF(COUNTIF($C$5:C8,C8)=1,MAX($P$4:P7)+1,"")) | Q8: =IF(D8="","",IF(COUNTIF($D$5:D8,D8)=1,MAX($Q$4:Q7)+1,""))
A9: 5 | B9: =IF($E9="","","PS-"&TEXT($A9,"000")) | M9: =IF(L9="","",IF(ISNUMBER(L9),L9,IFERROR(VALUE(LEFT(TRIM(L9),FIND(" ",TRIM(L9))-1))*VLOOKUP(LEFT(LOWER(TRIM(MID(TRIM(L9),FIND(" ",TRIM(L9))+1,99))),3),DurationUnits,2,FALSE),""))) | N9: =IF($I9<>"Yes","",IF($A9="","",COUNTIFS($A$5:$A$49,"<"&$A9,$I$5:$I$49,"Yes")+1)) | O9: =IF($E9="","",IFERROR(IF(INDEX('07. BIA'!$AA$6:$AA$285,MATCH($E9,'07. BIA'!$E$6:$E$285,0))="","",INDEX('07. BIA'!$AA$6:$AA$285,MATCH($E9,'07. BIA'!$E$6:$E$285,0))),"")) | P9: =IF(C9="","",IF(COUNTIF($C$5:C9,C9)=1,MAX($P$4:P8)+1,"")) | Q9: =IF(D9="","",IF(COUNTIF($D$5:D9,D9)=1,MAX($Q$4:Q8)+1,""))
A10: 6 | B10: =IF($E10="","","PS-"&TEXT($A10,"000")) | M10: =IF(L10="","",IF(ISNUMBER(L10),L10,IFERROR(VALUE(LEFT(TRIM(L10),FIND(" ",TRIM(L10))-1))*VLOOKUP(LEFT(LOWER(TRIM(MID(TRIM(L10),FIND(" ",TRIM(L10))+1,99))),3),DurationUnits,2,FALSE),""))) | N10: =IF($I10<>"Yes","",IF($A10="","",COUNTIFS($A$5:$A$49,"<"&$A10,$I$5:$I$49,"Yes")+1)) | O10: =IF($E10="","",IFERROR(IF(INDEX('07. BIA'!$AA$6:$AA$285,MATCH($E10,'07. BIA'!$E$6:$E$285,0))="","",INDEX('07. BIA'!$AA$6:$AA$285,MATCH($E10,'07. BIA'!$E$6:$E$285,0))),"")) | P10: =IF(C10="","",IF(COUNTIF($C$5:C10,C10)=1,MAX($P$4:P9)+1,"")) | Q10: =IF(D10="","",IF(COUNTIF($D$5:D10,D10)=1,MAX($Q$4:Q9)+1,""))
A11: 7 | B11: =IF($E11="","","PS-"&TEXT($A11,"000")) | M11: =IF(L11="","",IF(ISNUMBER(L11),L11,IFERROR(VALUE(LEFT(TRIM(L11),FIND(" ",TRIM(L11))-1))*VLOOKUP(LEFT(LOWER(TRIM(MID(TRIM(L11),FIND(" ",TRIM(L11))+1,99))),3),DurationUnits,2,FALSE),""))) | N11: =IF($I11<>"Yes","",IF($A11="","",COUNTIFS($A$5:$A$49,"<"&$A11,$I$5:$I$49,"Yes")+1)) | O11: =IF($E11="","",IFERROR(IF(INDEX('07. BIA'!$AA$6:$AA$285,MATCH($E11,'07. BIA'!$E$6:$E$285,0))="","",INDEX('07. BIA'!$AA$6:$AA$285,MATCH($E11,'07. BIA'!$E$6:$E$285,0))),"")) | P11: =IF(C11="","",IF(COUNTIF($C$5:C11,C11)=1,MAX($P$4:P10)+1,"")) | Q11: =IF(D11="","",IF(COUNTIF($D$5:D11,D11)=1,MAX($Q$4:Q10)+1,""))
A12: 8 | B12: =IF($E12="","","PS-"&TEXT($A12,"000")) | M12: =IF(L12="","",IF(ISNUMBER(L12),L12,IFERROR(VALUE(LEFT(TRIM(L12),FIND(" ",TRIM(L12))-1))*VLOOKUP(LEFT(LOWER(TRIM(MID(TRIM(L12),FIND(" ",TRIM(L12))+1,99))),3),DurationUnits,2,FALSE),""))) | N12: =IF($I12<>"Yes","",IF($A12="","",COUNTIFS($A$5:$A$49,"<"&$A12,$I$5:$I$49,"Yes")+1)) | O12: =IF($E12="","",IFERROR(IF(INDEX('07. BIA'!$AA$6:$AA$285,MATCH($E12,'07. BIA'!$E$6:$E$285,0))="","",INDEX('07. BIA'!$AA$6:$AA$285,MATCH($E12,'07. BIA'!$E$6:$E$285,0))),"")) | P12: =IF(C12="","",IF(COUNTIF($C$5:C12,C12)=1,MAX($P$4:P11)+1,"")) | Q12: =IF(D12="","",IF(COUNTIF($D$5:D12,D12)=1,MAX($Q$4:Q11)+1,""))
A13: 9 | B13: =IF($E13="","","PS-"&TEXT($A13,"000")) | M13: =IF(L13="","",IF(ISNUMBER(L13),L13,IFERROR(VALUE(LEFT(TRIM(L13),FIND(" ",TRIM(L13))-1))*VLOOKUP(LEFT(LOWER(TRIM(MID(TRIM(L13),FIND(" ",TRIM(L13))+1,99))),3),DurationUnits,2,FALSE),""))) | N13: =IF($I13<>"Yes","",IF($A13="","",COUNTIFS($A$5:$A$49,"<"&$A13,$I$5:$I$49,"Yes")+1)) | O13: =IF($E13="","",IFERROR(IF(INDEX('07. BIA'!$AA$6:$AA$285,MATCH($E13,'07. BIA'!$E$6:$E$285,0))="","",INDEX('07. BIA'!$AA$6:$AA$285,MATCH($E13,'07. BIA'!$E$6:$E$285,0))),"")) | P13: =IF(C13="","",IF(COUNTIF($C$5:C13,C13)=1,MAX($P$4:P12)+1,"")) | Q13: =IF(D13="","",IF(COUNTIF($D$5:D13,D13)=1,MAX($Q$4:Q12)+1,""))
A14: 10 | B14: =IF($E14="","","PS-"&TEXT($A14,"000")) | M14: =IF(L14="","",IF(ISNUMBER(L14),L14,IFERROR(VALUE(LEFT(TRIM(L14),FIND(" ",TRIM(L14))-1))*VLOOKUP(LEFT(LOWER(TRIM(MID(TRIM(L14),FIND(" ",TRIM(L14))+1,99))),3),DurationUnits,2,FALSE),""))) | N14: =IF($I14<>"Yes","",IF($A14="","",COUNTIFS($A$5:$A$49,"<"&$A14,$I$5:$I$49,"Yes")+1)) | O14: =IF($E14="","",IFERROR(IF(INDEX('07. BIA'!$AA$6:$AA$285,MATCH($E14,'07. BIA'!$E$6:$E$285,0))="","",INDEX('07. BIA'!$AA$6:$AA$285,MATCH($E14,'07. BIA'!$E$6:$E$285,0))),"")) | P14: =IF(C14="","",IF(COUNTIF($C$5:C14,C14)=1,MAX($P$4:P13)+1,"")) | Q14: =IF(D14="","",IF(COUNTIF($D$5:D14,D14)=1,MAX($Q$4:Q13)+1,""))
A15: 11 | B15: =IF($E15="","","PS-"&TEXT($A15,"000")) | M15: =IF(L15="","",IF(ISNUMBER(L15),L15,IFERROR(VALUE(LEFT(TRIM(L15),FIND(" ",TRIM(L15))-1))*VLOOKUP(LEFT(LOWER(TRIM(MID(TRIM(L15),FIND(" ",TRIM(L15))+1,99))),3),DurationUnits,2,FALSE),""))) | N15: =IF($I15<>"Yes","",IF($A15="","",COUNTIFS($A$5:$A$49,"<"&$A15,$I$5:$I$49,"Yes")+1)) | O15: =IF($E15="","",IFERROR(IF(INDEX('07. BIA'!$AA$6:$AA$285,MATCH($E15,'07. BIA'!$E$6:$E$285,0))="","",INDEX('07. BIA'!$AA$6:$AA$285,MATCH($E15,'07. BIA'!$E$6:$E$285,0))),"")) | P15: =IF(C15="","",IF(COUNTIF($C$5:C15,C15)=1,MAX($P$4:P14)+1,"")) | Q15: =IF(D15="","",IF(COUNTIF($D$5:D15,D15)=1,MAX($Q$4:Q14)+1,""))
A16: 12 | B16: =IF($E16="","","PS-"&TEXT($A16,"000")) | M16: =IF(L16="","",IF(ISNUMBER(L16),L16,IFERROR(VALUE(LEFT(TRIM(L16),FIND(" ",TRIM(L16))-1))*VLOOKUP(LEFT(LOWER(TRIM(MID(TRIM(L16),FIND(" ",TRIM(L16))+1,99))),3),DurationUnits,2,FALSE),""))) | N16: =IF($I16<>"Yes","",IF($A16="","",COUNTIFS($A$5:$A$49,"<"&$A16,$I$5:$I$49,"Yes")+1)) | O16: =IF($E16="","",IFERROR(IF(INDEX('07. BIA'!$AA$6:$AA$285,MATCH($E16,'07. BIA'!$E$6:$E$285,0))="","",INDEX('07. BIA'!$AA$6:$AA$285,MATCH($E16,'07. BIA'!$E$6:$E$285,0))),"")) | P16: =IF(C16="","",IF(COUNTIF($C$5:C16,C16)=1,MAX($P$4:P15)+1,"")) | Q16: =IF(D16="","",IF(COUNTIF($D$5:D16,D16)=1,MAX($Q$4:Q15)+1,""))
... A49: 45 | B49: =IF($E49="","","PS-"&TEXT($A49,"000")) | M49: =IF(L49="","",IF(ISNUMBER(L49),L49,IFERROR(VALUE(LEFT(TRIM(L49),FIND(" ",TRIM(L49))-1))*VLOOKUP(LEFT(LOWER(TRIM(MID(TRIM(L49),FIND(" ",TRIM(L49))+1,99))),3),DurationUnits,2,FALSE),""))) | N49: =IF($I49<>"Yes","",IF($A49="","",COUNTIFS($A$5:$A$49,"<"&$A49,$I$5:$I$49,"Yes")+1)) | O49: =IF($E49="","",IFERROR(IF(INDEX('07. BIA'!$AA$6:$AA$285,MATCH($E49,'07. BIA'!$E$6:$E$285,0))="","",INDEX('07. BIA'!$AA$6:$AA$285,MATCH($E49,'07. BIA'!$E$6:$E$285,0))),"")) | P49: =IF(C49="","",IF(COUNTIF($C$5:C49,C49)=1,MAX($P$4:P48)+1,"")) | Q49: =IF(D49="","",IF(COUNTIF($D$5:D49,D49)=1,MAX($Q$4:Q48)+1,""))

Sheet 05. Processes & Activities
A1: Scope: Organization Products & Services
A4: Sl # | B4: Product Code | C4: Product & Services | D4: Activities performed within the process | E4: Frequency of Activity | F4: Peak Period | G4: Rationale for Peak Period | H4: Current Staff to Perform Activity | I4: Activity Can be Performed Remotely? | J4: BlA level MTPD in hours | K4: BIA Level RTO in hours | L4: Remark
A5: 1 | C5: =IF(B5="","",IFERROR(VLOOKUP(B5,'04. Products & Services'!$B$5:$E$49,4,FALSE),"")) | J5: =IF($B5="","",IFERROR(IF(INDEX('07. BIA'!$AA$6:$AA$285,MATCH($B5,'07. BIA'!$F$6:$F$285,0))="","",INDEX('07. BIA'!$AA$6:$AA$285,MATCH($B5,'07. BIA'!$F$6:$F$285,0))),"")) | K5: =IF($B5="","",IFERROR(IF(INDEX('07. BIA'!$AD$6:$AD$285,MATCH($B5,'07. BIA'!$F$6:$F$285,0))="","",INDEX('07. BIA'!$AD$6:$AD$285,MATCH($B5,'07. BIA'!$F$6:$F$285,0))),""))
A6: 2 | C6: =IF(B6="","",IFERROR(VLOOKUP(B6,'04. Products & Services'!$B$5:$E$49,4,FALSE),"")) | J6: =IF($B6="","",IFERROR(IF(INDEX('07. BIA'!$AA$6:$AA$285,MATCH($B6,'07. BIA'!$F$6:$F$285,0))="","",INDEX('07. BIA'!$AA$6:$AA$285,MATCH($B6,'07. BIA'!$F$6:$F$285,0))),"")) | K6: =IF($B6="","",IFERROR(IF(INDEX('07. BIA'!$AD$6:$AD$285,MATCH($B6,'07. BIA'!$F$6:$F$285,0))="","",INDEX('07. BIA'!$AD$6:$AD$285,MATCH($B6,'07. BIA'!$F$6:$F$285,0))),""))
A7: 3 | C7: =IF(B7="","",IFERROR(VLOOKUP(B7,'04. Products & Services'!$B$5:$E$49,4,FALSE),"")) | J7: =IF($B7="","",IFERROR(IF(INDEX('07. BIA'!$AA$6:$AA$285,MATCH($B7,'07. BIA'!$F$6:$F$285,0))="","",INDEX('07. BIA'!$AA$6:$AA$285,MATCH($B7,'07. BIA'!$F$6:$F$285,0))),"")) | K7: =IF($B7="","",IFERROR(IF(INDEX('07. BIA'!$AD$6:$AD$285,MATCH($B7,'07. BIA'!$F$6:$F$285,0))="","",INDEX('07. BIA'!$AD$6:$AD$285,MATCH($B7,'07. BIA'!$F$6:$F$285,0))),""))
A8: 4 | C8: =IF(B8="","",IFERROR(VLOOKUP(B8,'04. Products & Services'!$B$5:$E$49,4,FALSE),"")) | J8: =IF($B8="","",IFERROR(IF(INDEX('07. BIA'!$AA$6:$AA$285,MATCH($B8,'07. BIA'!$F$6:$F$285,0))="","",INDEX('07. BIA'!$AA$6:$AA$285,MATCH($B8,'07. BIA'!$F$6:$F$285,0))),"")) | K8: =IF($B8="","",IFERROR(IF(INDEX('07. BIA'!$AD$6:$AD$285,MATCH($B8,'07. BIA'!$F$6:$F$285,0))="","",INDEX('07. BIA'!$AD$6:$AD$285,MATCH($B8,'07. BIA'!$F$6:$F$285,0))),""))
A9: 5 | C9: =IF(B9="","",IFERROR(VLOOKUP(B9,'04. Products & Services'!$B$5:$E$49,4,FALSE),"")) | J9: =IF($B9="","",IFERROR(IF(INDEX('07. BIA'!$AA$6:$AA$285,MATCH($B9,'07. BIA'!$F$6:$F$285,0))="","",INDEX('07. BIA'!$AA$6:$AA$285,MATCH($B9,'07. BIA'!$F$6:$F$285,0))),"")) | K9: =IF($B9="","",IFERROR(IF(INDEX('07. BIA'!$AD$6:$AD$285,MATCH($B9,'07. BIA'!$F$6:$F$285,0))="","",INDEX('07. BIA'!$AD$6:$AD$285,MATCH($B9,'07. BIA'!$F$6:$F$285,0))),""))
A10: 6 | C10: =IF(B10="","",IFERROR(VLOOKUP(B10,'04. Products & Services'!$B$5:$E$49,4,FALSE),"")) | J10: =IF($B10="","",IFERROR(IF(INDEX('07. BIA'!$AA$6:$AA$285,MATCH($B10,'07. BIA'!$F$6:$F$285,0))="","",INDEX('07. BIA'!$AA$6:$AA$285,MATCH($B10,'07. BIA'!$F$6:$F$285,0))),"")) | K10: =IF($B10="","",IFERROR(IF(INDEX('07. BIA'!$AD$6:$AD$285,MATCH($B10,'07. BIA'!$F$6:$F$285,0))="","",INDEX('07. BIA'!$AD$6:$AD$285,MATCH($B10,'07. BIA'!$F$6:$F$285,0))),""))
A11: 7 | C11: =IF(B11="","",IFERROR(VLOOKUP(B11,'04. Products & Services'!$B$5:$E$49,4,FALSE),"")) | J11: =IF($B11="","",IFERROR(IF(INDEX('07. BIA'!$AA$6:$AA$285,MATCH($B11,'07. BIA'!$F$6:$F$285,0))="","",INDEX('07. BIA'!$AA$6:$AA$285,MATCH($B11,'07. BIA'!$F$6:$F$285,0))),"")) | K11: =IF($B11="","",IFERROR(IF(INDEX('07. BIA'!$AD$6:$AD$285,MATCH($B11,'07. BIA'!$F$6:$F$285,0))="","",INDEX('07. BIA'!$AD$6:$AD$285,MATCH($B11,'07. BIA'!$F$6:$F$285,0))),""))
A12: 8 | C12: =IF(B12="","",IFERROR(VLOOKUP(B12,'04. Products & Services'!$B$5:$E$49,4,FALSE),"")) | J12: =IF($B12="","",IFERROR(IF(INDEX('07. BIA'!$AA$6:$AA$285,MATCH($B12,'07. BIA'!$F$6:$F$285,0))="","",INDEX('07. BIA'!$AA$6:$AA$285,MATCH($B12,'07. BIA'!$F$6:$F$285,0))),"")) | K12: =IF($B12="","",IFERROR(IF(INDEX('07. BIA'!$AD$6:$AD$285,MATCH($B12,'07. BIA'!$F$6:$F$285,0))="","",INDEX('07. BIA'!$AD$6:$AD$285,MATCH($B12,'07. BIA'!$F$6:$F$285,0))),""))
A13: 9 | C13: =IF(B13="","",IFERROR(VLOOKUP(B13,'04. Products & Services'!$B$5:$E$49,4,FALSE),"")) | J13: =IF($B13="","",IFERROR(IF(INDEX('07. BIA'!$AA$6:$AA$285,MATCH($B13,'07. BIA'!$F$6:$F$285,0))="","",INDEX('07. BIA'!$AA$6:$AA$285,MATCH($B13,'07. BIA'!$F$6:$F$285,0))),"")) | K13: =IF($B13="","",IFERROR(IF(INDEX('07. BIA'!$AD$6:$AD$285,MATCH($B13,'07. BIA'!$F$6:$F$285,0))="","",INDEX('07. BIA'!$AD$6:$AD$285,MATCH($B13,'07. BIA'!$F$6:$F$285,0))),""))
A14: 10 | C14: =IF(B14="","",IFERROR(VLOOKUP(B14,'04. Products & Services'!$B$5:$E$49,4,FALSE),"")) | J14: =IF($B14="","",IFERROR(IF(INDEX('07. BIA'!$AA$6:$AA$285,MATCH($B14,'07. BIA'!$F$6:$F$285,0))="","",INDEX('07. BIA'!$AA$6:$AA$285,MATCH($B14,'07. BIA'!$F$6:$F$285,0))),"")) | K14: =IF($B14="","",IFERROR(IF(INDEX('07. BIA'!$AD$6:$AD$285,MATCH($B14,'07. BIA'!$F$6:$F$285,0))="","",INDEX('07. BIA'!$AD$6:$AD$285,MATCH($B14,'07. BIA'!$F$6:$F$285,0))),""))
A15: 11 | C15: =IF(B15="","",IFERROR(VLOOKUP(B15,'04. Products & Services'!$B$5:$E$49,4,FALSE),"")) | J15: =IF($B15="","",IFERROR(IF(INDEX('07. BIA'!$AA$6:$AA$285,MATCH($B15,'07. BIA'!$F$6:$F$285,0))="","",INDEX('07. BIA'!$AA$6:$AA$285,MATCH($B15,'07. BIA'!$F$6:$F$285,0))),"")) | K15: =IF($B15="","",IFERROR(IF(INDEX('07. BIA'!$AD$6:$AD$285,MATCH($B15,'07. BIA'!$F$6:$F$285,0))="","",INDEX('07. BIA'!$AD$6:$AD$285,MATCH($B15,'07. BIA'!$F$6:$F$285,0))),""))
A16: 12 | C16: =IF(B16="","",IFERROR(VLOOKUP(B16,'04. Products & Services'!$B$5:$E$49,4,FALSE),"")) | J16: =IF($B16="","",IFERROR(IF(INDEX('07. BIA'!$AA$6:$AA$285,MATCH($B16,'07. BIA'!$F$6:$F$285,0))="","",INDEX('07. BIA'!$AA$6:$AA$285,MATCH($B16,'07. BIA'!$F$6:$F$285,0))),"")) | K16: =IF($B16="","",IFERROR(IF(INDEX('07. BIA'!$AD$6:$AD$285,MATCH($B16,'07. BIA'!$F$6:$F$285,0))="","",INDEX('07. BIA'!$AD$6:$AD$285,MATCH($B16,'07. BIA'!$F$6:$F$285,0))),""))
... A211: 207 | C211: =IF(B211="","",IFERROR(VLOOKUP(B211,'04. Products & Services'!$B$5:$E$49,4,FALSE),"")) | J211: =IF($B211="","",IFERROR(IF(INDEX('07. BIA'!$AA$6:$AA$285,MATCH($B211,'07. BIA'!$F$6:$F$285,0))="","",INDEX('07. BIA'!$AA$6:$AA$285,MATCH($B211,'07. BIA'!$F$6:$F$285,0))),"")) | K211: =IF($B211="","",IFERROR(IF(INDEX('07. BIA'!$AD$6:$AD$285,MATCH($B211,'07. BIA'!$F$6:$F$285,0))="","",INDEX('07. BIA'!$AD$6:$AD$285,MATCH($B211,'07. BIA'!$F$6:$F$285,0))),""))

Sheet 06. Application & Equipment
A1: Application equip list
A5: Note: | B5: Here list of applications and services related to IT and equipment and applications related to OT to be captured by BU team.
F8: Sl # | G8: ICT | I8: Equipment / Building / Utilities
A9: IT dependencies | C9: Sub dependencies | F9: Sl # | G9: Application | H9: Service | I9: Equipment / Building / Utilities
A10: ICT | C10: Application | F10: 1
A11: Equipment / Building / Utilities | C11: Service | F11: 2
C12: Equipment / Building / Utilities | F12: 3
F13: 4
F14: 5
F15: 6
F16: 7
F17: 8
F18: 9
F19: 10
F20: 11
F21: 12
F22: 13
F23: 14
F24: 15
... F34: 25

Sheet 07. BIA
A1: Business Impact Analysis (Product & Service Level)
A4: No. | B4: BIA # | C4: Business Unit | D4: Division / Site | E4: Product / Service (auto - value-chain order) | F4: Product / Service ID | G4: Risk Identification | I4: Impact Type | J4: Process Unavailability Impact Over Time (1-5) - anchors in Sheet 9 | S4: Criticality (Corporate cascade) | X4: MBCO & Recovery Targets | AH4: Linked Records (auto)
G5: Dependencies | H5: Will it interrupt the operation? (Y/N) | J5: Up to 6 Hours | K5: Up to 18 Hours | L5: Up to 36 Hours | M5: Up to 3 Days | N5: Up to 1 Week | O5: Up to 2 Weeks | P5: Up to 3 Weeks | Q5: Up to 1 month | R5: More than 1 Month | S5: Max Impact (auto) | T5: Max Impact Type (auto) | U5: Corporate Critical (auto) | V5: BU Critical (Y/N) | W5: Critical - Final (auto) | X5: MBCO - Corporate (auto) | Y5: MBCO - BU | Z5: Rationale / Supporting Reasons | AA5: MTPD (auto) hours | AB5: CEO MTPD | AC5: RTO | AD5: RTO (auto) in hours | AE5: RPO (fill if Data/ICT = Yes) in hours | AF5: Assessment Date | AG5: Valid Until (auto +12 mo) | AH5: Risk IDs | AI5: S&S # | AJ5: R&R IDs
A6: 1 | B6: =IF($E6="","","BIA-"&TEXT(1,"000")) | C6: =IFERROR(INDEX(BusinessUnits1,MATCH($A6,'04. Products & Services'!$N$5:$N$49,0)),"") | D6: =IFERROR(INDEX(DivisionSites,MATCH($A6,'04. Products & Services'!$N$5:$N$49,0)),"") | E6: =IFERROR(INDEX(ScopeNames,MATCH($A6,'04. Products & Services'!$N$5:$N$49,0)),"") | F6: =IF($E6="","",IFERROR(IF(INDEX(PS_ID,MATCH($E6,ScopeNames,0))="","",INDEX(PS_ID,MATCH($E6,ScopeNames,0))),"")) | G6: People | I6: Financial | S6: =IF(COUNT(J6:R12)=0,"",MAX(J6:R12)) | T6: =IF($S$6="","",IF(COUNT(J6:R6)=0,"",IF(MAX(J6:R6)>3,$I6,""))) | U6: =IF($E6="","",IFERROR(IF(INDEX('04. Products & Services'!$J$5:$J$49,MATCH($A6,'04. Products & Services'!$N$5:$N$49,0))="","",INDEX('04. Products & Services'!$J$5:$J$49,MATCH($A6,'04. Products & Services'!$N$5:$N$49,0))),"")) | W6: =IF($E6="","",IF(OR($U6="Yes",$V6="Yes"),"Yes",IF(AND($U6="No",$V6="No"),"No",IF(AND($U6="Under Evaluation",$V6="No"),"Under Evaluation","")))) | X6: =IF($E6="","",IFERROR(IF(INDEX('04. Products & Services'!$K$5:$K$49,MATCH($A6,'04. Products & Services'!$N$5:$N$49,0))="","",INDEX('04. Products & Services'!$K$5:$K$49,MATCH($A6,'04. Products & Services'!$N$5:$N$49,0))),"")) | AA6: =IF($E6="","",IF(COUNT(J6:R12)=0,"",IF(MAX(J6:J12)>=4,6,IF(MAX(K6:K12)>=4,18,IF(MAX(L6:L12)>=4,36,IF(MAX(M6:M12)>=4,72,IF(MAX(N6:N12)>=4,168,IF(MAX(O6:O12)>=4,336,IF(MAX(P6:P12)>=4,504,IF(MAX(Q6:Q12)>=4,672,IF(MAX(R6:R12)>=4,"",""))))))))))) | AB6: =IF($E6="","",IFERROR(IF(INDEX('04. Products & Services'!$M$5:$M$49,MATCH($A6,'04. Products & Services'!$N$5:$N$49,0))="","",INDEX('04. Products & Services'!$M$5:$M$49,MATCH($A6,'04. Products & Services'!$N$5:$N$49,0))),"")) | AD6: =IF(AC6="","",IF(ISNUMBER(AC6),AC6,IFERROR(VALUE(LEFT(TRIM(AC6),FIND(" ",TRIM(AC6))-1))*VLOOKUP(LEFT(LOWER(TRIM(MID(TRIM(AC6),FIND(" ",TRIM(AC6))+1,99))),3),DurationUnits,2,FALSE),""))) | AG6: =IF($AF6="","",EDATE($AF6,12)) | AH6: {=IF($B6="","",_xlfn.LET(_xlpm.ids,'15. BCM Risk Register'!$A$6:$A$65,_xlpm.links,'15. BCM Risk Register'!$I$6:$I$65,_xlpm.hit,ISNUMBER(SEARCH(","&$B6&",",","&SUBSTITUTE(_xlpm.links," ","")&",")),IFERROR(_xlfn.TEXTJOIN(", ",TRUE,_xlfn.UNIQUE(_xlfn._xlws.FILTER(_xlpm.ids,_xlpm.hit*(_xlpm.ids<>"")))),"Not Created")))} | AI6: {=IF($B6="","",_xlfn.LET(_xlpm.ids,'15. BCM Risk Register'!$L$6:$L$65,_xlpm.links,'15. BCM Risk Register'!$I$6:$I$65,_xlpm.hit,ISNUMBER(SEARCH(","&$B6&",",","&SUBSTITUTE(_xlpm.links," ","")&",")),IFERROR(_xlfn.TEXTJOIN(", ",TRUE,_xlfn.UNIQUE(_xlfn._xlws.FILTER(_xlpm.ids,_xlpm.hit*(_xlpm.ids<>"")*(_xlpm.ids<>"Not Created")))),"Not Created")))} | AJ6: {=IF($B6="","",_xlfn.LET(_xlpm.ids,'15. BCM Risk Register'!$K$6:$K$65,_xlpm.links,'15. BCM Risk Register'!$I$6:$I$65,_xlpm.hit,ISNUMBER(SEARCH(","&$B6&",",","&SUBSTITUTE(_xlpm.links," ","")&",")),IFERROR(_xlfn.TEXTJOIN(", ",TRUE,_xlfn.UNIQUE(_xlfn._xlws.FILTER(_xlpm.ids,_xlpm.hit*(_xlpm.ids<>"")*(_xlpm.ids<>"Not Created")))),"Not Created")))}
G7: ICT | I7: Operational | T7: =IF($S$6="","",IF(COUNT(J7:R7)=0,"",IF(MAX(J7:R7)>3,$I7,"")))
G8: Data / Info | I8: Product / Service Safety | T8: =IF($S$6="","",IF(COUNT(J8:R8)=0,"",IF(MAX(J8:R8)>3,$I8,"")))
G9: 3rd Party | I9: Health, Safety & Environment | T9: =IF($S$6="","",IF(COUNT(J9:R9)=0,"",IF(MAX(J9:R9)>3,$I9,"")))
G10: Equipment / Building / Utilities | I10: Regulatory & Compliance | T10: =IF($S$6="","",IF(COUNT(J10:R10)=0,"",IF(MAX(J10:R10)>3,$I10,"")))
G11: Pre-Service | I11: Reputation | T11: =IF($S$6="","",IF(COUNT(J11:R11)=0,"",IF(MAX(J11:R11)>3,$I11,"")))
G12: Post-Service | I12: Information Technology | T12: =IF($S$6="","",IF(COUNT(J12:R12)=0,"",IF(MAX(J12:R12)>3,$I12,"")))
A13: 2 | B13: =IF($E13="","","BIA-"&TEXT(2,"000")) | C13: =IFERROR(INDEX(BusinessUnits1,MATCH($A13,'04. Products & Services'!$N$5:$N$49,0)),"") | D13: =IFERROR(INDEX(DivisionSites,MATCH($A13,'04. Products & Services'!$N$5:$N$49,0)),"") | E13: =IFERROR(INDEX(ScopeNames,MATCH($A13,'04. Products & Services'!$N$5:$N$49,0)),"") | F13: =IF($E13="","",IFERROR(IF(INDEX(PS_ID,MATCH($E13,ScopeNames,0))="","",INDEX(PS_ID,MATCH($E13,ScopeNames,0))),"")) | G13: People | I13: Financial | S13: =IF(COUNT(J13:R19)=0,"",MAX(J13:R19)) | T13: =IF($S$13="","",IF(COUNT(J13:R13)=0,"",IF(MAX(J13:R13)>3,$I13,""))) | U13: =IF($E13="","",IFERROR(IF(INDEX('04. Products & Services'!$J$5:$J$49,MATCH($A13,'04. Products & Services'!$N$5:$N$49,0))="","",INDEX('04. Products & Services'!$J$5:$J$49,MATCH($A13,'04. Products & Services'!$N$5:$N$49,0))),"")) | W13: =IF($E13="","",IF(OR($U13="Yes",$V13="Yes"),"Yes",IF(AND($U13="No",$V13="No"),"No",IF(AND($U13="Under Evaluation",$V13="No"),"Under Evaluation","")))) | X13: =IF($E13="","",IFERROR(IF(INDEX('04. Products & Services'!$K$5:$K$49,MATCH($A13,'04. Products & Services'!$N$5:$N$49,0))="","",INDEX('04. Products & Services'!$K$5:$K$49,MATCH($A13,'04. Products & Services'!$N$5:$N$49,0))),"")) | AA13: =IF($E13="","",IF(COUNT(J13:R19)=0,"",IF(MAX(J13:J19)>=4,6,IF(MAX(K13:K19)>=4,18,IF(MAX(L13:L19)>=4,36,IF(MAX(M13:M19)>=4,72,IF(MAX(N13:N19)>=4,168,IF(MAX(O13:O19)>=4,336,IF(MAX(P13:P19)>=4,504,IF(MAX(Q13:Q19)>=4,672,IF(MAX(R13:R19)>=4,"",""))))))))))) | AB13: =IF($E13="","",IFERROR(IF(INDEX('04. Products & Services'!$M$5:$M$49,MATCH($A13,'04. Products & Services'!$N$5:$N$49,0))="","",INDEX('04. Products & Services'!$M$5:$M$49,MATCH($A13,'04. Products & Services'!$N$5:$N$49,0))),"")) | AD13: =IF(AC13="","",IF(ISNUMBER(AC13),AC13,IFERROR(VALUE(LEFT(TRIM(AC13),FIND(" ",TRIM(AC13))-1))*VLOOKUP(LEFT(LOWER(TRIM(MID(TRIM(AC13),FIND(" ",TRIM(AC13))+1,99))),3),DurationUnits,2,FALSE),""))) | AG13: =IF($AF13="","",EDATE($AF13,12)) | AH13: {=IF($B13="","",_xlfn.LET(_xlpm.ids,'15. BCM Risk Register'!$A$6:$A$65,_xlpm.links,'15. BCM Risk Register'!$I$6:$I$65,_xlpm.hit,ISNUMBER(SEARCH(","&$B13&",",","&SUBSTITUTE(_xlpm.links," ","")&",")),IFERROR(_xlfn.TEXTJOIN(", ",TRUE,_xlfn.UNIQUE(_xlfn._xlws.FILTER(_xlpm.ids,_xlpm.hit*(_xlpm.ids<>"")))),"Not Created")))} | AI13: {=IF($B13="","",_xlfn.LET(_xlpm.ids,'15. BCM Risk Register'!$L$6:$L$65,_xlpm.links,'15. BCM Risk Register'!$I$6:$I$65,_xlpm.hit,ISNUMBER(SEARCH(","&$B13&",",","&SUBSTITUTE(_xlpm.links," ","")&",")),IFERROR(_xlfn.TEXTJOIN(", ",TRUE,_xlfn.UNIQUE(_xlfn._xlws.FILTER(_xlpm.ids,_xlpm.hit*(_xlpm.ids<>"")*(_xlpm.ids<>"Not Created")))),"Not Created")))} | AJ13: {=IF($B13="","",_xlfn.LET(_xlpm.ids,'15. BCM Risk Register'!$K$6:$K$65,_xlpm.links,'15. BCM Risk Register'!$I$6:$I$65,_xlpm.hit,ISNUMBER(SEARCH(","&$B13&",",","&SUBSTITUTE(_xlpm.links," ","")&",")),IFERROR(_xlfn.TEXTJOIN(", ",TRUE,_xlfn.UNIQUE(_xlfn._xlws.FILTER(_xlpm.ids,_xlpm.hit*(_xlpm.ids<>"")*(_xlpm.ids<>"Not Created")))),"Not Created")))}
G14: ICT | I14: Operational | T14: =IF($S$13="","",IF(COUNT(J14:R14)=0,"",IF(MAX(J14:R14)>3,$I14,"")))
G15: Data / Info | I15: Product / Service Safety | T15: =IF($S$13="","",IF(COUNT(J15:R15)=0,"",IF(MAX(J15:R15)>3,$I15,"")))
G16: 3rd Party | I16: Health, Safety & Environment | T16: =IF($S$13="","",IF(COUNT(J16:R16)=0,"",IF(MAX(J16:R16)>3,$I16,"")))
G17: Equipment / Building / Utilities | I17: Regulatory & Compliance | T17: =IF($S$13="","",IF(COUNT(J17:R17)=0,"",IF(MAX(J17:R17)>3,$I17,"")))
G18: Pre-Service | I18: Reputation | T18: =IF($S$13="","",IF(COUNT(J18:R18)=0,"",IF(MAX(J18:R18)>3,$I18,"")))
G19: Post-Service | I19: Information Technology | T19: =IF($S$13="","",IF(COUNT(J19:R19)=0,"",IF(MAX(J19:R19)>3,$I19,"")))
A20: 3 | B20: =IF($E20="","","BIA-"&TEXT(3,"000")) | C20: =IFERROR(INDEX(BusinessUnits1,MATCH($A20,'04. Products & Services'!$N$5:$N$49,0)),"") | D20: =IFERROR(INDEX(DivisionSites,MATCH($A20,'04. Products & Services'!$N$5:$N$49,0)),"") | E20: =IFERROR(INDEX(ScopeNames,MATCH($A20,'04. Products & Services'!$N$5:$N$49,0)),"") | F20: =IF($E20="","",IFERROR(IF(INDEX(PS_ID,MATCH($E20,ScopeNames,0))="","",INDEX(PS_ID,MATCH($E20,ScopeNames,0))),"")) | G20: People | I20: Financial | S20: =IF(COUNT(J20:R26)=0,"",MAX(J20:R26)) | T20: =IF($S$20="","",IF(COUNT(J20:R20)=0,"",IF(MAX(J20:R20)>3,$I20,""))) | U20: =IF($E20="","",IFERROR(IF(INDEX('04. Products & Services'!$J$5:$J$49,MATCH($A20,'04. Products & Services'!$N$5:$N$49,0))="","",INDEX('04. Products & Services'!$J$5:$J$49,MATCH($A20,'04. Products & Services'!$N$5:$N$49,0))),"")) | W20: =IF($E20="","",IF(OR($U20="Yes",$V20="Yes"),"Yes",IF(AND($U20="No",$V20="No"),"No",IF(AND($U20="Under Evaluation",$V20="No"),"Under Evaluation","")))) | X20: =IF($E20="","",IFERROR(IF(INDEX('04. Products & Services'!$K$5:$K$49,MATCH($A20,'04. Products & Services'!$N$5:$N$49,0))="","",INDEX('04. Products & Services'!$K$5:$K$49,MATCH($A20,'04. Products & Services'!$N$5:$N$49,0))),"")) | AA20: =IF($E20="","",IF(COUNT(J20:R26)=0,"",IF(MAX(J20:J26)>=4,6,IF(MAX(K20:K26)>=4,18,IF(MAX(L20:L26)>=4,36,IF(MAX(M20:M26)>=4,72,IF(MAX(N20:N26)>=4,168,IF(MAX(O20:O26)>=4,336,IF(MAX(P20:P26)>=4,504,IF(MAX(Q20:Q26)>=4,672,IF(MAX(R20:R26)>=4,"",""))))))))))) | AB20: =IF($E20="","",IFERROR(IF(INDEX('04. Products & Services'!$M$5:$M$49,MATCH($A20,'04. Products & Services'!$N$5:$N$49,0))="","",INDEX('04. Products & Services'!$M$5:$M$49,MATCH($A20,'04. Products & Services'!$N$5:$N$49,0))),"")) | AD20: =IF(AC20="","",IF(ISNUMBER(AC20),AC20,IFERROR(VALUE(LEFT(TRIM(AC20),FIND(" ",TRIM(AC20))-1))*VLOOKUP(LEFT(LOWER(TRIM(MID(TRIM(AC20),FIND(" ",TRIM(AC20))+1,99))),3),DurationUnits,2,FALSE),""))) | AG20: =IF($AF20="","",EDATE($AF20,12)) | AH20: {=IF($B20="","",_xlfn.LET(_xlpm.ids,'15. BCM Risk Register'!$A$6:$A$65,_xlpm.links,'15. BCM Risk Register'!$I$6:$I$65,_xlpm.hit,ISNUMBER(SEARCH(","&$B20&",",","&SUBSTITUTE(_xlpm.links," ","")&",")),IFERROR(_xlfn.TEXTJOIN(", ",TRUE,_xlfn.UNIQUE(_xlfn._xlws.FILTER(_xlpm.ids,_xlpm.hit*(_xlpm.ids<>"")))),"Not Created")))} | AI20: {=IF($B20="","",_xlfn.LET(_xlpm.ids,'15. BCM Risk Register'!$L$6:$L$65,_xlpm.links,'15. BCM Risk Register'!$I$6:$I$65,_xlpm.hit,ISNUMBER(SEARCH(","&$B20&",",","&SUBSTITUTE(_xlpm.links," ","")&",")),IFERROR(_xlfn.TEXTJOIN(", ",TRUE,_xlfn.UNIQUE(_xlfn._xlws.FILTER(_xlpm.ids,_xlpm.hit*(_xlpm.ids<>"")*(_xlpm.ids<>"Not Created")))),"Not Created")))} | AJ20: {=IF($B20="","",_xlfn.LET(_xlpm.ids,'15. BCM Risk Register'!$K$6:$K$65,_xlpm.links,'15. BCM Risk Register'!$I$6:$I$65,_xlpm.hit,ISNUMBER(SEARCH(","&$B20&",",","&SUBSTITUTE(_xlpm.links," ","")&",")),IFERROR(_xlfn.TEXTJOIN(", ",TRUE,_xlfn.UNIQUE(_xlfn._xlws.FILTER(_xlpm.ids,_xlpm.hit*(_xlpm.ids<>"")*(_xlpm.ids<>"Not Created")))),"Not Created")))}
G21: ICT | I21: Operational | T21: =IF($S$20="","",IF(COUNT(J21:R21)=0,"",IF(MAX(J21:R21)>3,$I21,"")))
G22: Data / Info | I22: Product / Service Safety | T22: =IF($S$20="","",IF(COUNT(J22:R22)=0,"",IF(MAX(J22:R22)>3,$I22,"")))
G23: 3rd Party | I23: Health, Safety & Environment | T23: =IF($S$20="","",IF(COUNT(J23:R23)=0,"",IF(MAX(J23:R23)>3,$I23,"")))
G24: Equipment / Building / Utilities | I24: Regulatory & Compliance | T24: =IF($S$20="","",IF(COUNT(J24:R24)=0,"",IF(MAX(J24:R24)>3,$I24,"")))
G25: Pre-Service | I25: Reputation | T25: =IF($S$20="","",IF(COUNT(J25:R25)=0,"",IF(MAX(J25:R25)>3,$I25,"")))
G26: Post-Service | I26: Information Technology | T26: =IF($S$20="","",IF(COUNT(J26:R26)=0,"",IF(MAX(J26:R26)>3,$I26,"")))
A27: 4 | B27: =IF($E27="","","BIA-"&TEXT(4,"000")) | C27: =IFERROR(INDEX(BusinessUnits1,MATCH($A27,'04. Products & Services'!$N$5:$N$49,0)),"") | D27: =IFERROR(INDEX(DivisionSites,MATCH($A27,'04. Products & Services'!$N$5:$N$49,0)),"") | E27: =IFERROR(INDEX(ScopeNames,MATCH($A27,'04. Products & Services'!$N$5:$N$49,0)),"") | F27: =IF($E27="","",IFERROR(IF(INDEX(PS_ID,MATCH($E27,ScopeNames,0))="","",INDEX(PS_ID,MATCH($E27,ScopeNames,0))),"")) | G27: People | I27: Financial | S27: =IF(COUNT(J27:R33)=0,"",MAX(J27:R33)) | T27: =IF($S$27="","",IF(COUNT(J27:R27)=0,"",IF(MAX(J27:R27)>3,$I27,""))) | U27: =IF($E27="","",IFERROR(IF(INDEX('04. Products & Services'!$J$5:$J$49,MATCH($A27,'04. Products & Services'!$N$5:$N$49,0))="","",INDEX('04. Products & Services'!$J$5:$J$49,MATCH($A27,'04. Products & Services'!$N$5:$N$49,0))),"")) | W27: =IF($E27="","",IF(OR($U27="Yes",$V27="Yes"),"Yes",IF(AND($U27="No",$V27="No"),"No",IF(AND($U27="Under Evaluation",$V27="No"),"Under Evaluation","")))) | X27: =IF($E27="","",IFERROR(IF(INDEX('04. Products & Services'!$K$5:$K$49,MATCH($A27,'04. Products & Services'!$N$5:$N$49,0))="","",INDEX('04. Products & Services'!$K$5:$K$49,MATCH($A27,'04. Products & Services'!$N$5:$N$49,0))),"")) | AA27: =IF($E27="","",IF(COUNT(J27:R33)=0,"",IF(MAX(J27:J33)>=4,6,IF(MAX(K27:K33)>=4,18,IF(MAX(L27:L33)>=4,36,IF(MAX(M27:M33)>=4,72,IF(MAX(N27:N33)>=4,168,IF(MAX(O27:O33)>=4,336,IF(MAX(P27:P33)>=4,504,IF(MAX(Q27:Q33)>=4,672,IF(MAX(R27:R33)>=4,"",""))))))))))) | AB27: =IF($E27="","",IFERROR(IF(INDEX('04. Products & Services'!$M$5:$M$49,MATCH($A27,'04. Products & Services'!$N$5:$N$49,0))="","",INDEX('04. Products & Services'!$M$5:$M$49,MATCH($A27,'04. Products & Services'!$N$5:$N$49,0))),"")) | AD27: =IF(AC27="","",IF(ISNUMBER(AC27),AC27,IFERROR(VALUE(LEFT(TRIM(AC27),FIND(" ",TRIM(AC27))-1))*VLOOKUP(LEFT(LOWER(TRIM(MID(TRIM(AC27),FIND(" ",TRIM(AC27))+1,99))),3),DurationUnits,2,FALSE),""))) | AG27: =IF($AF27="","",EDATE($AF27,12)) | AH27: {=IF($B27="","",_xlfn.LET(_xlpm.ids,'15. BCM Risk Register'!$A$6:$A$65,_xlpm.links,'15. BCM Risk Register'!$I$6:$I$65,_xlpm.hit,ISNUMBER(SEARCH(","&$B27&",",","&SUBSTITUTE(_xlpm.links," ","")&",")),IFERROR(_xlfn.TEXTJOIN(", ",TRUE,_xlfn.UNIQUE(_xlfn._xlws.FILTER(_xlpm.ids,_xlpm.hit*(_xlpm.ids<>"")))),"Not Created")))} | AI27: {=IF($B27="","",_xlfn.LET(_xlpm.ids,'15. BCM Risk Register'!$L$6:$L$65,_xlpm.links,'15. BCM Risk Register'!$I$6:$I$65,_xlpm.hit,ISNUMBER(SEARCH(","&$B27&",",","&SUBSTITUTE(_xlpm.links," ","")&",")),IFERROR(_xlfn.TEXTJOIN(", ",TRUE,_xlfn.UNIQUE(_xlfn._xlws.FILTER(_xlpm.ids,_xlpm.hit*(_xlpm.ids<>"")*(_xlpm.ids<>"Not Created")))),"Not Created")))} | AJ27: {=IF($B27="","",_xlfn.LET(_xlpm.ids,'15. BCM Risk Register'!$K$6:$K$65,_xlpm.links,'15. BCM Risk Register'!$I$6:$I$65,_xlpm.hit,ISNUMBER(SEARCH(","&$B27&",",","&SUBSTITUTE(_xlpm.links," ","")&",")),IFERROR(_xlfn.TEXTJOIN(", ",TRUE,_xlfn.UNIQUE(_xlfn._xlws.FILTER(_xlpm.ids,_xlpm.hit*(_xlpm.ids<>"")*(_xlpm.ids<>"Not Created")))),"Not Created")))}
G28: ICT | I28: Operational | T28: =IF($S$27="","",IF(COUNT(J28:R28)=0,"",IF(MAX(J28:R28)>3,$I28,"")))
G29: Data / Info | I29: Product / Service Safety | T29: =IF($S$27="","",IF(COUNT(J29:R29)=0,"",IF(MAX(J29:R29)>3,$I29,"")))
G30: 3rd Party | I30: Health, Safety & Environment | T30: =IF($S$27="","",IF(COUNT(J30:R30)=0,"",IF(MAX(J30:R30)>3,$I30,"")))
G31: Equipment / Building / Utilities | I31: Regulatory & Compliance | T31: =IF($S$27="","",IF(COUNT(J31:R31)=0,"",IF(MAX(J31:R31)>3,$I31,"")))
G32: Pre-Service | I32: Reputation | T32: =IF($S$27="","",IF(COUNT(J32:R32)=0,"",IF(MAX(J32:R32)>3,$I32,"")))
G33: Post-Service | I33: Information Technology | T33: =IF($S$27="","",IF(COUNT(J33:R33)=0,"",IF(MAX(J33:R33)>3,$I33,"")))
A34: 5 | B34: =IF($E34="","","BIA-"&TEXT(5,"000")) | C34: =IFERROR(INDEX(BusinessUnits1,MATCH($A34,'04. Products & Services'!$N$5:$N$49,0)),"") | D34: =IFERROR(INDEX(DivisionSites,MATCH($A34,'04. Products & Services'!$N$5:$N$49,0)),"") | E34: =IFERROR(INDEX(ScopeNames,MATCH($A34,'04. Products & Services'!$N$5:$N$49,0)),"") | F34: =IF($E34="","",IFERROR(IF(INDEX(PS_ID,MATCH($E34,ScopeNames,0))="","",INDEX(PS_ID,MATCH($E34,ScopeNames,0))),"")) | G34: People | I34: Financial | S34: =IF(COUNT(J34:R40)=0,"",MAX(J34:R40)) | T34: =IF($S$34="","",IF(COUNT(J34:R34)=0,"",IF(MAX(J34:R34)>3,$I34,""))) | U34: =IF($E34="","",IFERROR(IF(INDEX('04. Products & Services'!$J$5:$J$49,MATCH($A34,'04. Products & Services'!$N$5:$N$49,0))="","",INDEX('04. Products & Services'!$J$5:$J$49,MATCH($A34,'04. Products & Services'!$N$5:$N$49,0))),"")) | W34: =IF($E34="","",IF(OR($U34="Yes",$V34="Yes"),"Yes",IF(AND($U34="No",$V34="No"),"No",IF(AND($U34="Under Evaluation",$V34="No"),"Under Evaluation","")))) | X34: =IF($E34="","",IFERROR(IF(INDEX('04. Products & Services'!$K$5:$K$49,MATCH($A34,'04. Products & Services'!$N$5:$N$49,0))="","",INDEX('04. Products & Services'!$K$5:$K$49,MATCH($A34,'04. Products & Services'!$N$5:$N$49,0))),"")) | AA34: =IF($E34="","",IF(COUNT(J34:R40)=0,"",IF(MAX(J34:J40)>=4,6,IF(MAX(K34:K40)>=4,18,IF(MAX(L34:L40)>=4,36,IF(MAX(M34:M40)>=4,72,IF(MAX(N34:N40)>=4,168,IF(MAX(O34:O40)>=4,336,IF(MAX(P34:P40)>=4,504,IF(MAX(Q34:Q40)>=4,672,IF(MAX(R34:R40)>=4,"",""))))))))))) | AB34: =IF($E34="","",IFERROR(IF(INDEX('04. Products & Services'!$M$5:$M$49,MATCH($A34,'04. Products & Services'!$N$5:$N$49,0))="","",INDEX('04. Products & Services'!$M$5:$M$49,MATCH($A34,'04. Products & Services'!$N$5:$N$49,0))),"")) | AD34: =IF(AC34="","",IF(ISNUMBER(AC34),AC34,IFERROR(VALUE(LEFT(TRIM(AC34),FIND(" ",TRIM(AC34))-1))*VLOOKUP(LEFT(LOWER(TRIM(MID(TRIM(AC34),FIND(" ",TRIM(AC34))+1,99))),3),DurationUnits,2,FALSE),""))) | AG34: =IF($AF34="","",EDATE($AF34,12)) | AH34: {=IF($B34="","",_xlfn.LET(_xlpm.ids,'15. BCM Risk Register'!$A$6:$A$65,_xlpm.links,'15. BCM Risk Register'!$I$6:$I$65,_xlpm.hit,ISNUMBER(SEARCH(","&$B34&",",","&SUBSTITUTE(_xlpm.links," ","")&",")),IFERROR(_xlfn.TEXTJOIN(", ",TRUE,_xlfn.UNIQUE(_xlfn._xlws.FILTER(_xlpm.ids,_xlpm.hit*(_xlpm.ids<>"")))),"Not Created")))} | AI34: {=IF($B34="","",_xlfn.LET(_xlpm.ids,'15. BCM Risk Register'!$L$6:$L$65,_xlpm.links,'15. BCM Risk Register'!$I$6:$I$65,_xlpm.hit,ISNUMBER(SEARCH(","&$B34&",",","&SUBSTITUTE(_xlpm.links," ","")&",")),IFERROR(_xlfn.TEXTJOIN(", ",TRUE,_xlfn.UNIQUE(_xlfn._xlws.FILTER(_xlpm.ids,_xlpm.hit*(_xlpm.ids<>"")*(_xlpm.ids<>"Not Created")))),"Not Created")))} | AJ34: {=IF($B34="","",_xlfn.LET(_xlpm.ids,'15. BCM Risk Register'!$K$6:$K$65,_xlpm.links,'15. BCM Risk Register'!$I$6:$I$65,_xlpm.hit,ISNUMBER(SEARCH(","&$B34&",",","&SUBSTITUTE(_xlpm.links," ","")&",")),IFERROR(_xlfn.TEXTJOIN(", ",TRUE,_xlfn.UNIQUE(_xlfn._xlws.FILTER(_xlpm.ids,_xlpm.hit*(_xlpm.ids<>"")*(_xlpm.ids<>"Not Created")))),"Not Created")))}
G35: ICT | I35: Operational | T35: =IF($S$34="","",IF(COUNT(J35:R35)=0,"",IF(MAX(J35:R35)>3,$I35,"")))
G36: Data / Info | I36: Product / Service Safety | T36: =IF($S$34="","",IF(COUNT(J36:R36)=0,"",IF(MAX(J36:R36)>3,$I36,"")))
G37: 3rd Party | I37: Health, Safety & Environment | T37: =IF($S$34="","",IF(COUNT(J37:R37)=0,"",IF(MAX(J37:R37)>3,$I37,"")))
G38: Equipment / Building / Utilities | I38: Regulatory & Compliance | T38: =IF($S$34="","",IF(COUNT(J38:R38)=0,"",IF(MAX(J38:R38)>3,$I38,"")))
G39: Pre-Service | I39: Reputation | T39: =IF($S$34="","",IF(COUNT(J39:R39)=0,"",IF(MAX(J39:R39)>3,$I39,"")))
G40: Post-Service | I40: Information Technology | T40: =IF($S$34="","",IF(COUNT(J40:R40)=0,"",IF(MAX(J40:R40)>3,$I40,"")))
A41: 6 | B41: =IF($E41="","","BIA-"&TEXT(6,"000")) | C41: =IFERROR(INDEX(BusinessUnits1,MATCH($A41,'04. Products & Services'!$N$5:$N$49,0)),"") | D41: =IFERROR(INDEX(DivisionSites,MATCH($A41,'04. Products & Services'!$N$5:$N$49,0)),"") | E41: =IFERROR(INDEX(ScopeNames,MATCH($A41,'04. Products & Services'!$N$5:$N$49,0)),"") | F41: =IF($E41="","",IFERROR(IF(INDEX(PS_ID,MATCH($E41,ScopeNames,0))="","",INDEX(PS_ID,MATCH($E41,ScopeNames,0))),"")) | G41: People | I41: Financial | S41: =IF(COUNT(J41:R47)=0,"",MAX(J41:R47)) | T41: =IF($S$41="","",IF(COUNT(J41:R41)=0,"",IF(MAX(J41:R41)>3,$I41,""))) | U41: =IF($E41="","",IFERROR(IF(INDEX('04. Products & Services'!$J$5:$J$49,MATCH($A41,'04. Products & Services'!$N$5:$N$49,0))="","",INDEX('04. Products & Services'!$J$5:$J$49,MATCH($A41,'04. Products & Services'!$N$5:$N$49,0))),"")) | W41: =IF($E41="","",IF(OR($U41="Yes",$V41="Yes"),"Yes",IF(AND($U41="No",$V41="No"),"No",IF(AND($U41="Under Evaluation",$V41="No"),"Under Evaluation","")))) | X41: =IF($E41="","",IFERROR(IF(INDEX('04. Products & Services'!$K$5:$K$49,MATCH($A41,'04. Products & Services'!$N$5:$N$49,0))="","",INDEX('04. Products & Services'!$K$5:$K$49,MATCH($A41,'04. Products & Services'!$N$5:$N$49,0))),"")) | AA41: =IF($E41="","",IF(COUNT(J41:R47)=0,"",IF(MAX(J41:J47)>=4,6,IF(MAX(K41:K47)>=4,18,IF(MAX(L41:L47)>=4,36,IF(MAX(M41:M47)>=4,72,IF(MAX(N41:N47)>=4,168,IF(MAX(O41:O47)>=4,336,IF(MAX(P41:P47)>=4,504,IF(MAX(Q41:Q47)>=4,672,IF(MAX(R41:R47)>=4,"",""))))))))))) | AB41: =IF($E41="","",IFERROR(IF(INDEX('04. Products & Services'!$M$5:$M$49,MATCH($A41,'04. Products & Services'!$N$5:$N$49,0))="","",INDEX('04. Products & Services'!$M$5:$M$49,MATCH($A41,'04. Products & Services'!$N$5:$N$49,0))),"")) | AD41: =IF(AC41="","",IF(ISNUMBER(AC41),AC41,IFERROR(VALUE(LEFT(TRIM(AC41),FIND(" ",TRIM(AC41))-1))*VLOOKUP(LEFT(LOWER(TRIM(MID(TRIM(AC41),FIND(" ",TRIM(AC41))+1,99))),3),DurationUnits,2,FALSE),""))) | AG41: =IF($AF41="","",EDATE($AF41,12)) | AH41: {=IF($B41="","",_xlfn.LET(_xlpm.ids,'15. BCM Risk Register'!$A$6:$A$65,_xlpm.links,'15. BCM Risk Register'!$I$6:$I$65,_xlpm.hit,ISNUMBER(SEARCH(","&$B41&",",","&SUBSTITUTE(_xlpm.links," ","")&",")),IFERROR(_xlfn.TEXTJOIN(", ",TRUE,_xlfn.UNIQUE(_xlfn._xlws.FILTER(_xlpm.ids,_xlpm.hit*(_xlpm.ids<>"")))),"Not Created")))} | AI41: {=IF($B41="","",_xlfn.LET(_xlpm.ids,'15. BCM Risk Register'!$L$6:$L$65,_xlpm.links,'15. BCM Risk Register'!$I$6:$I$65,_xlpm.hit,ISNUMBER(SEARCH(","&$B41&",",","&SUBSTITUTE(_xlpm.links," ","")&",")),IFERROR(_xlfn.TEXTJOIN(", ",TRUE,_xlfn.UNIQUE(_xlfn._xlws.FILTER(_xlpm.ids,_xlpm.hit*(_xlpm.ids<>"")*(_xlpm.ids<>"Not Created")))),"Not Created")))} | AJ41: {=IF($B41="","",_xlfn.LET(_xlpm.ids,'15. BCM Risk Register'!$K$6:$K$65,_xlpm.links,'15. BCM Risk Register'!$I$6:$I$65,_xlpm.hit,ISNUMBER(SEARCH(","&$B41&",",","&SUBSTITUTE(_xlpm.links," ","")&",")),IFERROR(_xlfn.TEXTJOIN(", ",TRUE,_xlfn.UNIQUE(_xlfn._xlws.FILTER(_xlpm.ids,_xlpm.hit*(_xlpm.ids<>"")*(_xlpm.ids<>"Not Created")))),"Not Created")))}
G42: ICT | I42: Operational | T42: =IF($S$41="","",IF(COUNT(J42:R42)=0,"",IF(MAX(J42:R42)>3,$I42,"")))
...

Sheet 08. Dependency Register
A1: Dependency Register
A4: No. | B4: Dep ID | C4: BIA # (select) | D4: Product / Service (auto) | E4: Product / Service ID | F4: Category (select) | G4: Sub category (For ICT and Equipment) | H4: ICT/ Equipment details | I4: Dependency Name | J4: Description / Detail | K4: SPOF? (Y/N) | L4: Owner | M4: Remarks
A5: 1 | B5: =IF($I5="","","DEP-"&TEXT($A5,"000")) | D5: =IF($C5="","",IFERROR(IF(INDEX('07. BIA'!$E$6:$E$285,MATCH($C5,'07. BIA'!$B$6:$B$285,0))="","",INDEX('07. BIA'!$E$6:$E$285,MATCH($C5,'07. BIA'!$B$6:$B$285,0))),"")) | E5: =IF($C5="","",IFERROR(IF(INDEX('07. BIA'!$F$6:$F$285,MATCH($C5,'07. BIA'!$B$6:$B$285,0))="","",INDEX('07. BIA'!$F$6:$F$285,MATCH($C5,'07. BIA'!$B$6:$B$285,0))),""))
A6: 2 | B6: =IF($I6="","","DEP-"&TEXT($A6,"000")) | D6: =IF($C6="","",IFERROR(IF(INDEX('07. BIA'!$E$6:$E$285,MATCH($C6,'07. BIA'!$B$6:$B$285,0))="","",INDEX('07. BIA'!$E$6:$E$285,MATCH($C6,'07. BIA'!$B$6:$B$285,0))),"")) | E6: =IF($C6="","",IFERROR(IF(INDEX('07. BIA'!$F$6:$F$285,MATCH($C6,'07. BIA'!$B$6:$B$285,0))="","",INDEX('07. BIA'!$F$6:$F$285,MATCH($C6,'07. BIA'!$B$6:$B$285,0))),""))
A7: 3 | B7: =IF($I7="","","DEP-"&TEXT($A7,"000")) | D7: =IF($C7="","",IFERROR(IF(INDEX('07. BIA'!$E$6:$E$285,MATCH($C7,'07. BIA'!$B$6:$B$285,0))="","",INDEX('07. BIA'!$E$6:$E$285,MATCH($C7,'07. BIA'!$B$6:$B$285,0))),"")) | E7: =IF($C7="","",IFERROR(IF(INDEX('07. BIA'!$F$6:$F$285,MATCH($C7,'07. BIA'!$B$6:$B$285,0))="","",INDEX('07. BIA'!$F$6:$F$285,MATCH($C7,'07. BIA'!$B$6:$B$285,0))),""))
A8: 4 | B8: =IF($I8="","","DEP-"&TEXT($A8,"000")) | D8: =IF($C8="","",IFERROR(IF(INDEX('07. BIA'!$E$6:$E$285,MATCH($C8,'07. BIA'!$B$6:$B$285,0))="","",INDEX('07. BIA'!$E$6:$E$285,MATCH($C8,'07. BIA'!$B$6:$B$285,0))),"")) | E8: =IF($C8="","",IFERROR(IF(INDEX('07. BIA'!$F$6:$F$285,MATCH($C8,'07. BIA'!$B$6:$B$285,0))="","",INDEX('07. BIA'!$F$6:$F$285,MATCH($C8,'07. BIA'!$B$6:$B$285,0))),""))
A9: 5 | B9: =IF($I9="","","DEP-"&TEXT($A9,"000")) | D9: =IF($C9="","",IFERROR(IF(INDEX('07. BIA'!$E$6:$E$285,MATCH($C9,'07. BIA'!$B$6:$B$285,0))="","",INDEX('07. BIA'!$E$6:$E$285,MATCH($C9,'07. BIA'!$B$6:$B$285,0))),"")) | E9: =IF($C9="","",IFERROR(IF(INDEX('07. BIA'!$F$6:$F$285,MATCH($C9,'07. BIA'!$B$6:$B$285,0))="","",INDEX('07. BIA'!$F$6:$F$285,MATCH($C9,'07. BIA'!$B$6:$B$285,0))),""))
A10: 6 | B10: =IF($I10="","","DEP-"&TEXT($A10,"000")) | D10: =IF($C10="","",IFERROR(IF(INDEX('07. BIA'!$E$6:$E$285,MATCH($C10,'07. BIA'!$B$6:$B$285,0))="","",INDEX('07. BIA'!$E$6:$E$285,MATCH($C10,'07. BIA'!$B$6:$B$285,0))),"")) | E10: =IF($C10="","",IFERROR(IF(INDEX('07. BIA'!$F$6:$F$285,MATCH($C10,'07. BIA'!$B$6:$B$285,0))="","",INDEX('07. BIA'!$F$6:$F$285,MATCH($C10,'07. BIA'!$B$6:$B$285,0))),""))
A11: 7 | B11: =IF($I11="","","DEP-"&TEXT($A11,"000")) | D11: =IF($C11="","",IFERROR(IF(INDEX('07. BIA'!$E$6:$E$285,MATCH($C11,'07. BIA'!$B$6:$B$285,0))="","",INDEX('07. BIA'!$E$6:$E$285,MATCH($C11,'07. BIA'!$B$6:$B$285,0))),"")) | E11: =IF($C11="","",IFERROR(IF(INDEX('07. BIA'!$F$6:$F$285,MATCH($C11,'07. BIA'!$B$6:$B$285,0))="","",INDEX('07. BIA'!$F$6:$F$285,MATCH($C11,'07. BIA'!$B$6:$B$285,0))),""))
A12: 8 | B12: =IF($I12="","","DEP-"&TEXT($A12,"000")) | D12: =IF($C12="","",IFERROR(IF(INDEX('07. BIA'!$E$6:$E$285,MATCH($C12,'07. BIA'!$B$6:$B$285,0))="","",INDEX('07. BIA'!$E$6:$E$285,MATCH($C12,'07. BIA'!$B$6:$B$285,0))),"")) | E12: =IF($C12="","",IFERROR(IF(INDEX('07. BIA'!$F$6:$F$285,MATCH($C12,'07. BIA'!$B$6:$B$285,0))="","",INDEX('07. BIA'!$F$6:$F$285,MATCH($C12,'07. BIA'!$B$6:$B$285,0))),""))
A13: 9 | B13: =IF($I13="","","DEP-"&TEXT($A13,"000")) | D13: =IF($C13="","",IFERROR(IF(INDEX('07. BIA'!$E$6:$E$285,MATCH($C13,'07. BIA'!$B$6:$B$285,0))="","",INDEX('07. BIA'!$E$6:$E$285,MATCH($C13,'07. BIA'!$B$6:$B$285,0))),"")) | E13: =IF($C13="","",IFERROR(IF(INDEX('07. BIA'!$F$6:$F$285,MATCH($C13,'07. BIA'!$B$6:$B$285,0))="","",INDEX('07. BIA'!$F$6:$F$285,MATCH($C13,'07. BIA'!$B$6:$B$285,0))),""))
A14: 10 | B14: =IF($I14="","","DEP-"&TEXT($A14,"000")) | D14: =IF($C14="","",IFERROR(IF(INDEX('07. BIA'!$E$6:$E$285,MATCH($C14,'07. BIA'!$B$6:$B$285,0))="","",INDEX('07. BIA'!$E$6:$E$285,MATCH($C14,'07. BIA'!$B$6:$B$285,0))),"")) | E14: =IF($C14="","",IFERROR(IF(INDEX('07. BIA'!$F$6:$F$285,MATCH($C14,'07. BIA'!$B$6:$B$285,0))="","",INDEX('07. BIA'!$F$6:$F$285,MATCH($C14,'07. BIA'!$B$6:$B$285,0))),""))
A15: 11 | B15: =IF($I15="","","DEP-"&TEXT($A15,"000")) | D15: =IF($C15="","",IFERROR(IF(INDEX('07. BIA'!$E$6:$E$285,MATCH($C15,'07. BIA'!$B$6:$B$285,0))="","",INDEX('07. BIA'!$E$6:$E$285,MATCH($C15,'07. BIA'!$B$6:$B$285,0))),"")) | E15: =IF($C15="","",IFERROR(IF(INDEX('07. BIA'!$F$6:$F$285,MATCH($C15,'07. BIA'!$B$6:$B$285,0))="","",INDEX('07. BIA'!$F$6:$F$285,MATCH($C15,'07. BIA'!$B$6:$B$285,0))),""))
A16: 12 | B16: =IF($I16="","","DEP-"&TEXT($A16,"000")) | D16: =IF($C16="","",IFERROR(IF(INDEX('07. BIA'!$E$6:$E$285,MATCH($C16,'07. BIA'!$B$6:$B$285,0))="","",INDEX('07. BIA'!$E$6:$E$285,MATCH($C16,'07. BIA'!$B$6:$B$285,0))),"")) | E16: =IF($C16="","",IFERROR(IF(INDEX('07. BIA'!$F$6:$F$285,MATCH($C16,'07. BIA'!$B$6:$B$285,0))="","",INDEX('07. BIA'!$F$6:$F$285,MATCH($C16,'07. BIA'!$B$6:$B$285,0))),""))
... A204: 200 | B204: =IF($I204="","","DEP-"&TEXT($A204,"000")) | D204: =IF($C204="","",IFERROR(IF(INDEX('07. BIA'!$E$6:$E$285,MATCH($C204,'07. BIA'!$B$6:$B$285,0))="","",INDEX('07. BIA'!$E$6:$E$285,MATCH($C204,'07. BIA'!$B$6:$B$285,0))),"")) | E204: =IF($C204="","",IFERROR(IF(INDEX('07. BIA'!$F$6:$F$285,MATCH($C204,'07. BIA'!$B$6:$B$285,0))="","",INDEX('07. BIA'!$F$6:$F$285,MATCH($C204,'07. BIA'!$B$6:$B$285,0))),""))

Sheet 09. Risk Assumption Map
A1: BCM Risk Assessment by Dependency
A4: Dependency categories | C4: People | D4: ICT | E4: Data / Info | F4: 3rd Party | G4: Equipment / Building / Utilities | H4: Pre-Service | I4: Post-Service
A5: {=lstDepCat} | C5: Mass staff absence | D5: Cyberattack | E5: Critical data loss | F5: Critical supplier failure | G5: Critical site loss | H5: Critical material shortage | I5: Distribution network failure
C6: Key person loss | D6: Core application outage | E6: Traceability records unavailable | F6: Import route disruption | G6: Production line failure | H6: Feed or farm input shortage | I6: Warehouse or depot loss
C7: Skilled operator shortage | D7: Data centre or cloud outage | E7: Food-safety records unavailable | F7: Logistics provider failure | G7: Process utility outage | H7: Packaging shortage | I7: Fleet, fuel, or route disruption
C8: Staff unable to access site | D8: Network or communications outage | E8: Inventory or master-data failure | F8: External utility outage | G8: Cold-chain equipment failure | H8: Incoming material rejection | I8: Finished-goods cold-chain failure
C9: Workforce evacuation | D9: Backup or recovery failure | E9: Regulatory records unavailable | F9: Outsourced service failure | G9: Maintenance or spare-parts shortage | H9: Material stock-out | I9: Customer channel or demand disruption

Sheet 10. Risk Assessment
A1: BCM Risk Assessment by Dependency
A4: Slot | B4: Risk ID # / BIA # (assoc.) | C4: BU | D4: Division | E4: Dependency categories | F4: Applicable BIA #s | G4: Risk Assumption (select or type) / Associated Product / Service (auto) | H4: Business Disruption Scenario (auto) | I4: ERM / Site Risk Register Ref# | J4: Implemented Controls | K4: Residual Likelihood (1-5) | L4: Likelihood Rating (auto) | M4: Residual Impact (1-5) | N4: Impact Rating (auto) | O4: Risk Score (Likelihood × Impact) | P4: Risk Rating (auto) | Q4: BCP Priority (auto) 1=Critical...4=Low | R4: Remarks | S4: S&S # (auto) | T4: R&R IDs (auto) | U4: Risk Owner | V4: Assessment Date | W4: Review Date | X4: Approver | Y4: Evidence Reference | Z4: Source Completion
A5: 1 | B5: =IF($G5="","","RA-"&TEXT($A5,"000")) | F5: {=IF(C5="","",_xlfn.LET(_xlpm.bu,_xlfn.SCAN("",'07. BIA'!$C$6:$C$285,_xlfn.LAMBDA(_xlpm.a,_xlpm.v,IF(_xlpm.v="",_xlpm.a,_xlpm.v))),_xlpm.div,_xlfn.SCAN("",'07. BIA'!$D$6:$D$285,_xlfn.LAMBDA(_xlpm.a,_xlpm.v,IF(_xlpm.v="",_xlpm.a,_xlpm.v))),_xlpm.item,_xlfn.SCAN("",'07. BIA'!$E$6:$E$285,_xlfn.LAMBDA(_xlpm.a,_xlpm.v,IF(_xlpm.v="",_xlpm.a,_xlpm.v))),_xlpm.srcDep,LOWER(SUBSTITUTE(SUBSTITUTE(SUBSTITUTE('07. BIA'!$G$6:$G$285," ",""),"-",""),"/","")),_xlpm.rawKey,LOWER(SUBSTITUTE(SUBSTITUTE(SUBSTITUTE(E5," ",""),"-",""),"/","")),_xlpm.key,IF(_xlpm.rawKey="data","datainfo",_xlpm.rawKey),IF(D5="",IFERROR(_xlfn.TEXTJOIN(",",TRUE,_xlfn.UNIQUE(_xlfn._xlws.FILTER(_xlpm.item,(_xlpm.bu=C5)*(_xlpm.item<>"")))),""),IF(E5="","",IFERROR(_xlfn.TEXTJOIN(",",TRUE,_xlfn.UNIQUE(_xlfn._xlws.FILTER(_xlpm.item,(_xlpm.bu=C5)*(_xlpm.div=D5)*(_xlpm.srcDep=_xlpm.key)*('07. BIA'!$H$6:$H$285="Yes")))),"")))))} | H5: =IF($G5="","","Inability to deliver the associated products/services due to ["&$G5&"]") | L5: =IF($K5="","",CHOOSE($K5,"Rare","Infrequent","Occasional","Frequent","Almost Certain")) | N5: =IF($M5="","",CHOOSE($M5,"Negligible","Minor","Medium","Critical","Catastrophic")) | O5: =IF(OR($K5="",$M5=""),"",$K5*$M5) | P5: =IF($O5="","",IF($O5>=20,"Critical",IF($O5>=12,"Significant",IF($O5>=7,"Moderate","Low")))) | Q5: =IF($P5="","",IF($P5="Critical",1,IF($P5="Significant",2,IF($P5="Moderate",3,4)))) | S5: {=IF($B5="","",IFERROR(_xlfn.TEXTJOIN(",",TRUE,_xlfn.UNIQUE(_xlfn._xlws.FILTER('11. Strategies & Solutions'!$C$5:$C$64,('11. Strategies & Solutions'!$B$5:$B$64=$B5)*('11. Strategies & Solutions'!$C$5:$C$64<>"")))),"Not Created"))} | T5: {=IF($B5="","",_xlfn.LET(_xlpm.ss,_xlfn._xlws.FILTER('11. Strategies & Solutions'!$C$5:$C$64,('11. Strategies & Solutions'!$B$5:$B$64=$B5)*('11. Strategies & Solutions'!$C$5:$C$64<>""),""),IFERROR(_xlfn.TEXTJOIN(",",TRUE,_xlfn.UNIQUE(_xlfn._xlws.FILTER('14. Recovery & Response'!$B$5:$B$104,ISNUMBER(_xlfn.XMATCH('14. Recovery & Response'!$C$5:$C$104,_xlpm.ss))*('14. Recovery & Response'!$B$5:$B$104<>"")))),"Not Created")))} | Z5: =IF($B5="","",IF(AND($C5<>"",$D5<>"",$E5<>"",$F5<>"",$G5<>"",$H5<>"",$J5<>"",$K5<>"",$M5<>"",$U5<>"",ISNUMBER($V5),ISNUMBER($W5),$X5<>"",$Y5<>""),"Complete","Incomplete"))
A6: 2 | B6: =IF($G6="","","RA-"&TEXT($A6,"000")) | F6: {=IF(C6="","",_xlfn.LET(_xlpm.bu,_xlfn.SCAN("",'07. BIA'!$C$6:$C$285,_xlfn.LAMBDA(_xlpm.a,_xlpm.v,IF(_xlpm.v="",_xlpm.a,_xlpm.v))),_xlpm.div,_xlfn.SCAN("",'07. BIA'!$D$6:$D$285,_xlfn.LAMBDA(_xlpm.a,_xlpm.v,IF(_xlpm.v="",_xlpm.a,_xlpm.v))),_xlpm.item,_xlfn.SCAN("",'07. BIA'!$E$6:$E$285,_xlfn.LAMBDA(_xlpm.a,_xlpm.v,IF(_xlpm.v="",_xlpm.a,_xlpm.v))),_xlpm.srcDep,LOWER(SUBSTITUTE(SUBSTITUTE(SUBSTITUTE('07. BIA'!$G$6:$G$285," ",""),"-",""),"/","")),_xlpm.rawKey,LOWER(SUBSTITUTE(SUBSTITUTE(SUBSTITUTE(E6," ",""),"-",""),"/","")),_xlpm.key,IF(_xlpm.rawKey="data","datainfo",_xlpm.rawKey),IF(D6="",IFERROR(_xlfn.TEXTJOIN(",",TRUE,_xlfn.UNIQUE(_xlfn._xlws.FILTER(_xlpm.item,(_xlpm.bu=C6)*(_xlpm.item<>"")))),""),IF(E6="","",IFERROR(_xlfn.TEXTJOIN(",",TRUE,_xlfn.UNIQUE(_xlfn._xlws.FILTER(_xlpm.item,(_xlpm.bu=C6)*(_xlpm.div=D6)*(_xlpm.srcDep=_xlpm.key)*('07. BIA'!$H$6:$H$285="Yes")))),"")))))} | H6: =IF($G6="","","Inability to deliver the associated products/services due to ["&$G6&"]") | L6: =IF($K6="","",CHOOSE($K6,"Rare","Infrequent","Occasional","Frequent","Almost Certain")) | N6: =IF($M6="","",CHOOSE($M6,"Negligible","Minor","Medium","Critical","Catastrophic")) | O6: =IF(OR($K6="",$M6=""),"",$K6*$M6) | P6: =IF($O6="","",IF($O6>=20,"Critical",IF($O6>=12,"Significant",IF($O6>=7,"Moderate","Low")))) | Q6: =IF($P6="","",IF($P6="Critical",1,IF($P6="Significant",2,IF($P6="Moderate",3,4)))) | S6: {=IF($B6="","",IFERROR(_xlfn.TEXTJOIN(",",TRUE,_xlfn.UNIQUE(_xlfn._xlws.FILTER('11. Strategies & Solutions'!$C$5:$C$64,('11. Strategies & Solutions'!$B$5:$B$64=$B6)*('11. Strategies & Solutions'!$C$5:$C$64<>"")))),"Not Created"))} | T6: {=IF($B6="","",_xlfn.LET(_xlpm.ss,_xlfn._xlws.FILTER('11. Strategies & Solutions'!$C$5:$C$64,('11. Strategies & Solutions'!$B$5:$B$64=$B6)*('11. Strategies & Solutions'!$C$5:$C$64<>""),""),IFERROR(_xlfn.TEXTJOIN(",",TRUE,_xlfn.UNIQUE(_xlfn._xlws.FILTER('14. Recovery & Response'!$B$5:$B$104,ISNUMBER(_xlfn.XMATCH('14. Recovery & Response'!$C$5:$C$104,_xlpm.ss))*('14. Recovery & Response'!$B$5:$B$104<>"")))),"Not Created")))} | Z6: =IF($B6="","",IF(AND($C6<>"",$D6<>"",$E6<>"",$F6<>"",$G6<>"",$H6<>"",$J6<>"",$K6<>"",$M6<>"",$U6<>"",ISNUMBER($V6),ISNUMBER($W6),$X6<>"",$Y6<>""),"Complete","Incomplete"))
